Workbook

Sheet Plan stratégique  likewatt
A2: Plan stratégique
A5: Résumé stratégie
A6: Le plan stratégique est articulé autour de 3 axes : - la structuration et le renforcement de l'action commerciale et du marketing, avec un focus particulier sur Optiwize Leads - l'amélioration du produit (amélioration continue, extension fonctionnelle métier pour les installateurs et les developpeurs, batiment neufs et pilotage en production) - l'internationalisation vers l'Europe (adaption des produits aux spécificités nationales, filiales commerciales ES/CH/BE/DE)
A12: Milestones clés
A13: - Financement amélioration produit et développements spécifiques nationaux (500 k€) - Série A en 2027 entre 2,5 et 3M€ permettant de lancer l'internationalisation et l'accélération commerciale en France
A19: Scénario d'investissement
A20: Le scénario d'investissement privilégié est : Phase 1 : investissement produit et commercial suite à l'obtention d'un financement de 500 k€ sous forme de prêt. Phase 2 : Série A permettant de financer l'internationalisation et le renforcement commercial/marketing En l'absence de série A, le développement commercial se concentrera sur la France autour de Leads et des nouveaux produits.
A27: Scénario financier
A28: Selon le scénario standard privilégié d'une série A en juin 2027, la société générerait 43 M€ de revenus récurrents en 2032 (EBITDA à 49%). Le scénario conservateur prévoir 23M€ d'ARR et 23% d'EBITDA. Un décalge d'un des investissements en CH/BE/DE sera nécessaire ou un financemnt complémentaire de 500 k€. Dans le scénario standard alternatif d'une absence de série A, la société générerait 4,6 M€ de revenus en 2032 (EBITDA à 46%). Le scénario conservateur prévoir 2,4M€ d'ARR et 15% d'EBITDA avec un enjeu de trésorerie en S2 2027 en raison notamment du remboursement FTS. Un décalage des investissement R&D et marketing et le gel des recrutements sur une période de 18 mois ou un refinancemement seront nécessaire
B37: Scénarisation | F37: Stratégie investissement
B38: Acquisition Optiwize Pro | C38: Standard | F38: Début WP 3 R&D | G38: ='Annexe E Financement'!$B$20 -> 46082
B39: Modèle Leads | C39: Simulation | F39: Début ES | G39: =G43 -> 47515
B40: Adoption Leads | C40: Standard | F40: Début CH | G40: =G39+366 -> 47881
B41: Churn | C41: Standard | F41: Début BE | G41: =G40+366 -> 48247
B42: Montant levée | C42: 0 | F42: Début DE | G42: =G41+366 -> 48613
B43: Date levée | C43: 47515 | D43: 0 | F43: Début phase 2 FR | G43: =C43 -> 47515
B44: Point bas | C44: ='Prévisionnel annuel'!O10 -> 201756.47
B45: Date Point bas | C45: =Trésorerie!D32 -> 46722
B47: Date trésorerie négative | C47: =_xlfn.IFNA(Trésorerie!C33,"Pas avant 2032") -> Pas avant 2032

Sheet KPI
C3: Vente Optiwize Pro | D3: Adoption Leads | E3: Churn | G3: Modèle Leads | H3: Montant levée
B4: Scénario : | C4: ='Prévisionnel annuel'!O3 -> Standard | D4: ='Prévisionnel annuel'!O5 -> Standard | E4: ='Prévisionnel annuel'!O6 -> Standard | G4: ='Prévisionnel annuel'!O4 -> Simulation | H4: ='Prévisionnel annuel'!O7 -> 0
C8: 2025 | D8: 2026 | E8: 2027 | F8: 2028 | G8: 2029 | H8: 2030 | I8: 2031
B9: ARR (EoY) | C9: =C10+C11 -> 660000 | D9: =D10+D11 -> 836912.94 | E9: =E10+E11 -> 1213042.5 | F9: =F10+F11 -> 1704444.6 | G9: =G10+G11 -> 2329801.8 | H9: =H10+H11 -> 4016646.1 | I9: =I10+I11 -> 10524398
B10: ARR Optiwize Pro | C10: ='Prévisionnel annuel'!D6 -> 650000 | D10: =SUM(Ventes!J4:U4) -> 810992.44 | E10: =SUM(OFFSET(Ventes!$J4:$U4,0,12)) -> 1120863.3 | F10: =SUM(OFFSET(Ventes!$J4:$U4,0,24)) -> 1435720.1 | G10: =SUM(OFFSET(Ventes!$J4:$U4,0,36)) -> 1771593.8 | H10: =SUM(OFFSET(Ventes!$J4:$U4,0,48)) -> 2782173.8 | I10: =SUM(OFFSET(Ventes!$J4:$U4,0,60)) -> 6775579
B11: ARR Leads | C11: ='Prévisionnel annuel'!D7 -> 10000 | D11: =SUM(Ventes!J8:U8) -> 25920.503 | E11: =SUM(OFFSET(Ventes!$J8:$U8,0,12)) -> 92179.136 | F11: =SUM(OFFSET(Ventes!$J8:$U8,0,24)) -> 268724.54 | G11: =SUM(OFFSET(Ventes!$J8:$U8,0,36)) -> 558208.08 | H11: =SUM(OFFSET(Ventes!$J8:$U8,0,48)) -> 1234472.3 | I11: =SUM(OFFSET(Ventes!$J8:$U8,0,60)) -> 3748819.1
B12: # Clients (EoY) | C12: =C13 -> 177.65663 | D12: =D13 -> 224.53008 | E12: =E13 -> 284.65376 | F12: =F13 -> 348.07281 | G12: =G13 -> 416.73121 | H12: =H13 -> 826.35106 | I12: =I13 -> 2128.5565
B13: # Clients Optiwize Pro (EoY) | C13: =Ventes!I19 -> 177.65663 | D13: =Ventes!U19 -> 224.53008 | E13: =OFFSET(Ventes!$U$19,0,12) -> 284.65376 | F13: =OFFSET(Ventes!$U$19,0,24) -> 348.07281 | G13: =OFFSET(Ventes!$U$19,0,36) -> 416.73121 | H13: =OFFSET(Ventes!$U$19,0,48) -> 826.35106 | I13: =OFFSET(Ventes!$U$19,0,60) -> 2128.5565
B14: % Upsell Leads | C14: =Hypothèses!B71 -> 0.05 | D14: =Hypothèses!C71 -> 0.1 | E14: =Hypothèses!D71 -> 0.25 | F14: =Hypothèses!E71 -> 0.45 | G14: =Hypothèses!F71 -> 0.6 | H14: =Hypothèses!G71 -> 0.65 | I14: =Hypothèses!H71 -> 0.65
B15: % Projets simulés | C15: =Hypothèses!B72 -> 0.08 | D15: =Hypothèses!C72 -> 0.09 | E15: =Hypothèses!D72 -> 0.12 | F15: =Hypothèses!E72 -> 0.18 | G15: =Hypothèses!F72 -> 0.25 | H15: =Hypothèses!G72 -> 0.35 | I15: =Hypothèses!H72 -> 0.45
B16: EBITDA | C16: ='Prévisionnel annuel'!D14/'Prévisionnel annuel'!D5 -> -0.0628 | D16: ='Prévisionnel annuel'!E14/'Prévisionnel annuel'!E5 -> -0.32722408 | E16: ='Prévisionnel annuel'!F14/'Prévisionnel annuel'!F5 -> -0.15925648 | F16: ='Prévisionnel annuel'!G14/'Prévisionnel annuel'!G5 -> 0.090617986 | G16: ='Prévisionnel annuel'!H14/'Prévisionnel annuel'!H5 -> 0.22071401 | H16: ='Prévisionnel annuel'!I14/'Prévisionnel annuel'!I5 -> 0.037005179 | I16: ='Prévisionnel annuel'!J14/'Prévisionnel annuel'!J5 -> 0.25646799
B17: Trésorerie (EoY) | C17: =Trésorerie!I15 -> 471063.09 | D17: =OFFSET(Trésorerie!$I15,0,12) -> 494393.5 | E17: =OFFSET(Trésorerie!$I15,0,24) -> 201756.47 | F17: =OFFSET(Trésorerie!$I15,0,36) -> 460489.32 | G17: =OFFSET(Trésorerie!$I15,0,48) -> 1044551 | H17: =OFFSET(Trésorerie!$I15,0,60) -> 1284612.5 | I17: =OFFSET(Trésorerie!$I15,0,72) -> 3945708.3
B18: Equipe (EoY) | C18: ='Annexe A Plan RH'!$W92 -> 11 | D18: =OFFSET('Annexe A Plan RH'!$W92,0,12) -> 15 | E18: =OFFSET('Annexe A Plan RH'!$W92,0,24) -> 15 | F18: =OFFSET('Annexe A Plan RH'!$W92,0,36) -> 15 | G18: =OFFSET('Annexe A Plan RH'!$W92,0,48) -> 18 | H18: =OFFSET('Annexe A Plan RH'!$W92,0,60) -> 42 | I18: =OFFSET('Annexe A Plan RH'!$W92,0,72) -> 55

Sheet Prévisionnel annuel
N2: Scénarisation (Ne pas modifier ici) | R2: Stratégie investissement (Ne pas modifier ici)
C3: Année -1 | D3: Année 0 | E3: Année 1 | F3: Année 2 | G3: Année 3 | H3: Année 4 | I3: Année 5 | J3: Année 6 | K3: Année 7 | N3: Acquisition Optiwize Pro | O3: ='Plan stratégique likewatt'!C38 -> Standard | R3: ='Plan stratégique likewatt'!F38 -> Début WP 3 R&D | S3: ='Plan stratégique likewatt'!G38 -> 46082
C4: 2024 | D4: 2025 | E4: 2026 | F4: 2027 | G4: 2028 | H4: 2029 | I4: 2030 | J4: 2031 | K4: 2032 | N4: Modèle Leads | O4: ='Plan stratégique likewatt'!C39 -> Simulation | R4: ='Plan stratégique likewatt'!F39 -> Début ES | S4: ='Plan stratégique likewatt'!G39 -> 47515
B5: CA TOTAL | C5: =SUM(C6:C8) -> 643214 | D5: =SUM(D6:D8) -> 670000 | E5: =SUM(Ventes!J3:U3) -> 850072.77 | F5: =SUM(Ventes!V3:AG3) -> 1237725.3 | G5: =SUM(Ventes!AH3:AS3) -> 1732141.7 | H5: =SUM(Ventes!AT3:BE3) -> 2351078.7 | I5: =SUM(Ventes!BF3:BQ3) -> 4096388.5 | J5: =SUM(Ventes!BR3:CC3) -> 10768417 | K5: =SUM(Ventes!BH3:BS3) -> 4793848.7 | N5: Adoption Leads | O5: ='Plan stratégique likewatt'!C40 -> Standard | R5: ='Plan stratégique likewatt'!F40 -> Début CH | S5: ='Plan stratégique likewatt'!G40 -> 47881
B6: Optiwize Pro - Abonnement | C6: =549325+7118 -> 556443 | D6: 650000 | E6: =SUM(Ventes!J4:U4) -> 810992.44 | F6: =SUM(Ventes!V4:AG4) -> 1120863.3 | G6: =SUM(Ventes!AH4:AS4) -> 1435720.1 | H6: =SUM(Ventes!AT4:BE4) -> 1771593.8 | I6: =SUM(Ventes!BF4:BQ4) -> 2782173.8 | J6: =SUM(Ventes!BR4:CC4) -> 6775579 | K6: =SUM(Ventes!BH4:BS4) -> 3187995.2 | N6: Churn | O6: ='Plan stratégique likewatt'!C41 -> Standard | R6: ='Plan stratégique likewatt'!F41 -> Début BE | S6: ='Plan stratégique likewatt'!G41 -> 48247
B7: Leads - Pay as you go | C7: 0 | D7: 10000 | E7: =SUM(Ventes!J8:U8) -> 25920.503 | F7: =SUM(Ventes!V8:AG8) -> 92179.136 | G7: =SUM(Ventes!AH8:AS8) -> 268724.54 | H7: =SUM(Ventes!AT8:BE8) -> 558208.08 | I7: =SUM(Ventes!BF8:BQ8) -> 1234472.3 | J7: =SUM(Ventes!BR8:CC8) -> 3748819.1 | K7: =SUM(Ventes!BH8:BS8) -> 1506773.3 | N7: Montant levée | O7: ='Plan stratégique likewatt'!C42 -> 0 | R7: ='Plan stratégique likewatt'!F42 -> Début DE | S7: ='Plan stratégique likewatt'!G42 -> 48613
B8: Prestations de services (installations) | C8: =73040+3923+1710+8098 -> 86771 | D8: 10000 | E8: =SUM(Ventes!J12:U12) -> 13159.832 | F8: =SUM(Ventes!V12:AG12) -> 24682.854 | G8: =SUM(Ventes!AH12:AS12) -> 27697.077 | H8: =SUM(Ventes!AT12:BE12) -> 21276.838 | I8: =SUM(Ventes!BF12:BQ12) -> 79742.337 | J8: =SUM(Ventes!BR12:CC12) -> 244019.41 | K8: =SUM(Ventes!BH12:BS12) -> 99080.144 | N8: Date levée | O8: =EOMONTH('Plan stratégique likewatt'!C43,-1)+1 -> 47515 | R8: ='Plan stratégique likewatt'!F43 -> Début phase 2 FR | S8: ='Plan stratégique likewatt'!G43 -> 47515
B9: Productions immobilisées & stockées | C9: 0 | D9: 0 | E9: 0 | F9: 0 | G9: 0 | H9: 0 | I9: 0 | J9: 0 | K9: 0 | N9: Low point | O9: =Trésorerie!C33 -> #N/A
B10: MARGE BRUTE | C10: =C5+C11 -> 580814 | D10: =D5+D11 -> 667000 | E10: =E5+E11 -> 703478.5 | F10: =F5+F11 -> 946974.52 | G10: =G5+G11 -> 1281943.5 | H10: =H5+H11 -> 1772549.6 | I10: =I5+I11 -> 3035994.1 | J10: =J5+J11 -> 8125643 | K10: =K5+K11 -> 3568566.7 | N10: Low point | O10: =Trésorerie!C32 -> 201756.47 | P10: =Trésorerie!D32 -> 46722
B11: Couts variables, Sous-traitance | C11: -62400 | D11: -3000 | E11: =SUM('Couts variables'!J3:U3) -> -146594.28 | F11: =SUM('Couts variables'!V3:AG3) -> -290750.8 | G11: =SUM('Couts variables'!AH3:AS3) -> -450198.19 | H11: =SUM('Couts variables'!AT3:BE3) -> -578529.1 | I11: =SUM('Couts variables'!BF3:BQ3) -> -1060394.4 | J11: =SUM('Couts variables'!BR3:CC3) -> -2642774.5 | K11: =SUM('Couts variables'!BH3:BS3) -> -1225282
B12: VALEUR AJOUTEE | C12: =C10+C13 -> 493635 | D12: =D10+D13 -> 577000 | E12: =E10+E13 -> 494572.34 | F12: =F10+F13 -> 762534.6 | G12: =G10+G13 -> 1097058.8 | H12: =H10+H13 -> 1553971.7 | I12: =I10+I13 -> 2469425.9 | J12: =J10+J13 -> 6845274.9 | K12: =K10+K13 -> 2879470.2
B13: Couts fixes | C13: -87179 | D13: -90000 | E13: =SUM('Couts fixes'!J2:U2) -> -208906.16 | F13: =SUM('Couts fixes'!V2:AG2) -> -184439.92 | G13: =SUM('Couts fixes'!AH2:AS2) -> -184884.71 | H13: =SUM('Couts fixes'!AT2:BE2) -> -218577.93 | I13: =SUM('Couts fixes'!BF2:BQ2) -> -566568.2 | J13: =SUM('Couts fixes'!BR2:CC2) -> -1280368 | K13: =SUM('Couts fixes'!BH2:BS2) -> -689096.54
B14: EBE (EBITDA) | C14: =C12+C15+C16 -> 94334 | D14: =D12+D15+D16 -> -42076 | E14: =E12+E15+E16 -> -278164.28 | F14: =F12+F15+F16 -> -197115.78 | G14: =G12+G15+G16 -> 156963.19 | H14: =H12+H15+H16 -> 518915.99 | I14: =I12+I15+I16 -> 151587.59 | J14: =J12+J15+J16 -> 2761754.4 | K14: =K12+K15 -> 151328.17
B15: Salaires | C15: =-(343148+51982) -> -395130 | D15: =-53146*6-49200*6 -> -614076 | E15: =SUM('Couts RH'!J4:U4) -> -767965.62 | F15: =SUM('Couts RH'!V4:AG4) -> -954730.88 | G15: =SUM('Couts RH'!AH4:AS4) -> -935031.3 | H15: =SUM('Couts RH'!AT4:BE4) -> -1029839.7 | I15: =SUM('Couts RH'!BF4:BQ4) -> -2312465.9 | J15: =SUM('Couts RH'!BR4:CC4) -> -4077987 | K15: =SUM('Couts RH'!BH4:BS4) -> -2728142
B16: Impots, taxes (CFE, ...) | C16: -4171 | D16: -5000 | E16: =SUM('Couts fixes'!$J14:$U14) -> -4771 | F16: =SUM(OFFSET('Couts fixes'!$J14:$U14,0,12)) -> -4919.5108 | G16: =SUM(OFFSET('Couts fixes'!$J14:$U14,0,24)) -> -5064.3 | H16: =SUM(OFFSET('Couts fixes'!$J14:$U14,0,36)) -> -5215.92 | I16: =SUM(OFFSET('Couts fixes'!$J14:$U14,0,48)) -> -5372.3976 | J16: =SUM(OFFSET('Couts fixes'!$J14:$U14,0,60)) -> -5533.5695
B17: REX | C17: =C14+C18+C19 -> 101127 | D17: =D14+D18+D19 -> -48591 | E17: =E14+E18+E19 -> -287351.45 | F17: =F14+F18+F19 -> -207936.95 | G17: =G14+G18+G19 -> 144508.02 | H17: =H14+H18+H19 -> 499226.83 | I17: =I14+I18+I19 -> 116264.42 | J17: =J14+J18+J19 -> 2713397.2
B18: Amortissement | C18: -6515 | D18: -6515 | E18: =SUM(CAPEX!$C3:U3)/5 -> -9187.1667 | F18: =SUM(CAPEX!$C3:AG3)/5 -> -10821.167 | G18: =SUM(CAPEX!$C3:AS3)/5 -> -12455.167 | H18: =SUM(CAPEX!$C3:BE3)/5 -> -19689.167 | I18: =SUM(CAPEX!$C3:BQ3)/5 -> -35323.167 | J18: =SUM(CAPEX!$C3:CC3)/5 -> -48357.167
B19: Dépréciations, reprises comptable | C19: =12980+367-39 -> 13308 | D19: 0 | E19: 0 | F19: 0 | G19: 0 | H19: 0 | I19: 0 | J19: 0
B20: Resultat courant avant impots | C20: =C17+C21 -> 95410 | D20: =D17+D21 -> -54091 | E20: =E17+E21 -> -289526.45 | F20: =F17+F21 -> -209194.95 | G20: =G17+G21 -> 144166.02 | H20: =H17+H21 -> 499226.83 | I20: =I17+I21 -> 116264.42 | J20: =J17+J21 -> 2713397.2
B21: Résultat financier | C21: =-8717+3000 -> -5717 | D21: -5500 | E21: =SUM(OFFSET('Annexe E Financement'!$J11:$U11,0,0)) -> -2175 | F21: =SUM(OFFSET('Annexe E Financement'!$J11:$U11,0,12)) -> -1258 | G21: =SUM(OFFSET('Annexe E Financement'!$J11:$U11,0,24)) -> -342 | H21: =SUM(OFFSET('Annexe E Financement'!$J11:$U11,0,36)) -> 0 | I21: =SUM(OFFSET('Annexe E Financement'!$J11:$U11,0,49)) -> 0 | J21: =SUM(OFFSET('Annexe E Financement'!$J11:$U11,0,60)) -> 0
B22: Résultat de l'exercice | C22: =C20+C23+C24 -> 232614 | D22: =D20+D23+D24 -> 65909 | E22: =E20+E23+E24 -> -196765.51 | F22: =F20+F23+F24 -> -95105.886 | G22: =G20+G23+G24 -> 258255.09 | H22: =H20+H23+H24 -> 590615.48 | I22: =I20+I23+I24 -> 187256.67 | J22: =J20+J23+J24 -> 2988081.3
B23: Impots (IS, CIR,...) | C23: =137233 -> 137233 | D23: 120000 | E23: ='Annexe E Financement'!L39-IF(D20>0,D20*33%,0) -> 92760.938 | F23: ='Annexe E Financement'!X39-IF(E20>0,E20*33%,0) -> 114089.06 | G23: ='Annexe E Financement'!AJ39-IF(F20>0,F20*33%,0) -> 114089.06 | H23: ='Annexe E Financement'!AV39-IF(G20>0,G20*33%,0) -> 91388.649 | I23: ='Annexe E Financement'!BH39-IF(H20>0,H20*33%,0) -> 70992.245 | J23: ='Annexe E Financement'!BT39-IF(I20>0,I20*33%,0) -> 274684.11
B24: Produits et charges exceptionnels | C24: -29 | D24: 0 | E24: 0 | F24: 0 | G24: 0 | H24: 0 | I24: 0 | J24: 0
B25: CAF | C25: =C22-C18-C19 -> 225821 | D25: =D22-D18-D19 -> 72424 | E25: =E22-E18-E19 -> -187578.35 | F25: =F22-F18-F19 -> -84284.719 | G25: =G22-G18-G19 -> 270710.25 | H25: =H22-H18-H19 -> 610304.64 | I25: =I22-I18-I19 -> 222579.84 | J25: =J22-J18-J19 -> 3036438.5

Sheet Hypothèses
A2: Hypothèses marché
A3: Croissance organique marché FR | B3: 0.12
A4: Croissance organique marché ES | B4: 0.12
A5: Croissance organique marché CH | B5: 0.12
A6: Croissance organique marché BE | B6: 0.12
A7: Croissance organique marché DE | B7: 0.12
B9: 2025 | C9: 2026 | D9: 2027 | E9: 2028 | F9: 2029 | G9: 2030 | H9: 2031
A10: Hypothèses clients
A11: Nombre de projets/installateur
A12: FR | B12: 300 | C12: =B12*(1+$B3/2) -> 318 | D12: =C12*(1+$B3/2) -> 337.08 | E12: =D12*(1+$B3/2) -> 357.3048 | F12: =E12*(1+$B3/2) -> 378.74309 | G12: =F12*(1+$B3/2) -> 401.46767 | H12: =G12*(1+$B3/2) -> 425.55573
A13: ES | B13: 300 | C13: =B13*(1+$B4/2) -> 318 | D13: =C13*(1+$B4/2) -> 337.08 | E13: =D13*(1+$B4/2) -> 357.3048 | F13: =E13*(1+$B4/2) -> 378.74309 | G13: =F13*(1+$B4/2) -> 401.46767 | H13: =G13*(1+$B4/2) -> 425.55573
A14: CH | B14: 300 | C14: =B14*(1+$B5/2) -> 318 | D14: =C14*(1+$B5/2) -> 337.08 | E14: =D14*(1+$B5/2) -> 357.3048 | F14: =E14*(1+$B5/2) -> 378.74309 | G14: =F14*(1+$B5/2) -> 401.46767 | H14: =G14*(1+$B5/2) -> 425.55573
A15: BE | B15: 300 | C15: =B15*(1+$B6/2) -> 318 | D15: =C15*(1+$B6/2) -> 337.08 | E15: =D15*(1+$B6/2) -> 357.3048 | F15: =E15*(1+$B6/2) -> 378.74309 | G15: =F15*(1+$B6/2) -> 401.46767 | H15: =G15*(1+$B6/2) -> 425.55573
A16: DE | B16: 300 | C16: =B16*(1+$B7/2) -> 318 | D16: =C16*(1+$B7/2) -> 337.08 | E16: =D16*(1+$B7/2) -> 357.3048 | F16: =E16*(1+$B7/2) -> 378.74309 | G16: =F16*(1+$B7/2) -> 401.46767 | H16: =G16*(1+$B7/2) -> 425.55573
A19: Hypothèses commerciales
A20: Panier moyen mensuel Optiwize Pro | B20: ='Annexe G Evolution Portefeuill'!C$81/12 -> 329.71081 | C20: ='Annexe G Evolution Portefeuill'!D$81/12 -> 336.79557 | D20: ='Annexe G Evolution Portefeuill'!E$81/12 -> 363.71813 | E20: ='Annexe G Evolution Portefeuill'!F$81/12 -> 374.4191 | F20: ='Annexe G Evolution Portefeuill'!G$81/12 -> 385.19247 | G20: ='Annexe G Evolution Portefeuill'!H$81/12 -> 410.53172 | H20: ='Annexe G Evolution Portefeuill'!I$81/12 -> 412.85085
A21: FR | B21: =B20 -> 329.71081 | C21: =C20 -> 336.79557 | D21: =D20 -> 363.71813 | E21: =E20 -> 374.4191 | F21: =F20 -> 385.19247 | G21: =G20 -> 410.53172 | H21: =H20 -> 412.85085
A22: ES | B22: =B21 -> 329.71081 | C22: =C21 -> 336.79557 | D22: =D21 -> 363.71813 | E22: =E21 -> 374.4191 | F22: =F21 -> 385.19247 | G22: =G21 -> 410.53172 | H22: =H21 -> 412.85085
A23: CH | B23: =B22 -> 329.71081 | C23: =C22 -> 336.79557 | D23: =D22 -> 363.71813 | E23: =E22 -> 374.4191 | F23: =F22 -> 385.19247 | G23: =G22 -> 410.53172 | H23: =H22 -> 412.85085
A24: BE | B24: =B23 -> 329.71081 | C24: =C23 -> 336.79557 | D24: =D23 -> 363.71813 | E24: =E23 -> 374.4191 | F24: =F23 -> 385.19247 | G24: =G23 -> 410.53172 | H24: =H23 -> 412.85085
A25: DE | B25: =B24 -> 329.71081 | C25: =C24 -> 336.79557 | D25: =D24 -> 363.71813 | E25: =E24 -> 374.4191 | F25: =F24 -> 385.19247 | G25: =G24 -> 410.53172 | H25: =H24 -> 412.85085
A27: Panier moyen mensuel Leads
A28: FR | B28: {=_xlfn.IFS('Prévisionnel annuel'!$O$4="Simulation",B35,'Prévisionnel annuel'!$O$4="Succes",B42*$B$48*$B$47)} -> 35 | C28: {=_xlfn.IFS('Prévisionnel annuel'!$O$4="Simulation",C35,'Prévisionnel annuel'!$O$4="Succes",C42*$B$48*$B$47)} -> 35 | D28: {=_xlfn.IFS('Prévisionnel annuel'!$O$4="Simulation",D35,'Prévisionnel annuel'!$O$4="Succes",D42*$B$48*$B$47)} -> 35 | E28: {=_xlfn.IFS('Prévisionnel annuel'!$O$4="Simulation",E35,'Prévisionnel annuel'!$O$4="Succes",E42*$B$48*$B$47)} -> 35 | F28: {=_xlfn.IFS('Prévisionnel annuel'!$O$4="Simulation",F35,'Prévisionnel annuel'!$O$4="Succes",F42*$B$48*$B$47)} -> 35 | G28: {=_xlfn.IFS('Prévisionnel annuel'!$O$4="Simulation",G35,'Prévisionnel annuel'!$O$4="Succes",G42*$B$48*$B$47)} -> 35 | H28: {=_xlfn.IFS('Prévisionnel annuel'!$O$4="Simulation",H35,'Prévisionnel annuel'!$O$4="Succes",H42*$B$48*$B$47)} -> 35
A29: ES | B29: {=_xlfn.IFS('Prévisionnel annuel'!$O$4="Simulation",B36,'Prévisionnel annuel'!$O$4="Succes",B43*$B$48*$B$47)} -> 35 | C29: {=_xlfn.IFS('Prévisionnel annuel'!$O$4="Simulation",C36,'Prévisionnel annuel'!$O$4="Succes",C43*$B$48*$B$47)} -> 35 | D29: {=_xlfn.IFS('Prévisionnel annuel'!$O$4="Simulation",D36,'Prévisionnel annuel'!$O$4="Succes",D43*$B$48*$B$47)} -> 35 | E29: {=_xlfn.IFS('Prévisionnel annuel'!$O$4="Simulation",E36,'Prévisionnel annuel'!$O$4="Succes",E43*$B$48*$B$47)} -> 35 | F29: {=_xlfn.IFS('Prévisionnel annuel'!$O$4="Simulation",F36,'Prévisionnel annuel'!$O$4="Succes",F43*$B$48*$B$47)} -> 35 | G29: {=_xlfn.IFS('Prévisionnel annuel'!$O$4="Simulation",G36,'Prévisionnel annuel'!$O$4="Succes",G43*$B$48*$B$47)} -> 35 | H29: {=_xlfn.IFS('Prévisionnel annuel'!$O$4="Simulation",H36,'Prévisionnel annuel'!$O$4="Succes",H43*$B$48*$B$47)} -> 35
A30: CH | B30: {=_xlfn.IFS('Prévisionnel annuel'!$O$4="Simulation",B37,'Prévisionnel annuel'!$O$4="Succes",B44*$B$48*$B$47)} -> 35 | C30: {=_xlfn.IFS('Prévisionnel annuel'!$O$4="Simulation",C37,'Prévisionnel annuel'!$O$4="Succes",C44*$B$48*$B$47)} -> 35 | D30: {=_xlfn.IFS('Prévisionnel annuel'!$O$4="Simulation",D37,'Prévisionnel annuel'!$O$4="Succes",D44*$B$48*$B$47)} -> 35 | E30: {=_xlfn.IFS('Prévisionnel annuel'!$O$4="Simulation",E37,'Prévisionnel annuel'!$O$4="Succes",E44*$B$48*$B$47)} -> 35 | F30: {=_xlfn.IFS('Prévisionnel annuel'!$O$4="Simulation",F37,'Prévisionnel annuel'!$O$4="Succes",F44*$B$48*$B$47)} -> 35 | G30: {=_xlfn.IFS('Prévisionnel annuel'!$O$4="Simulation",G37,'Prévisionnel annuel'!$O$4="Succes",G44*$B$48*$B$47)} -> 35 | H30: {=_xlfn.IFS('Prévisionnel annuel'!$O$4="Simulation",H37,'Prévisionnel annuel'!$O$4="Succes",H44*$B$48*$B$47)} -> 35
A31: BE | B31: {=_xlfn.IFS('Prévisionnel annuel'!$O$4="Simulation",B38,'Prévisionnel annuel'!$O$4="Succes",B45*$B$48*$B$47)} -> 35 | C31: {=_xlfn.IFS('Prévisionnel annuel'!$O$4="Simulation",C38,'Prévisionnel annuel'!$O$4="Succes",C45*$B$48*$B$47)} -> 35 | D31: {=_xlfn.IFS('Prévisionnel annuel'!$O$4="Simulation",D38,'Prévisionnel annuel'!$O$4="Succes",D45*$B$48*$B$47)} -> 35 | E31: {=_xlfn.IFS('Prévisionnel annuel'!$O$4="Simulation",E38,'Prévisionnel annuel'!$O$4="Succes",E45*$B$48*$B$47)} -> 35 | F31: {=_xlfn.IFS('Prévisionnel annuel'!$O$4="Simulation",F38,'Prévisionnel annuel'!$O$4="Succes",F45*$B$48*$B$47)} -> 35 | G31: {=_xlfn.IFS('Prévisionnel annuel'!$O$4="Simulation",G38,'Prévisionnel annuel'!$O$4="Succes",G45*$B$48*$B$47)} -> 35 | H31: {=_xlfn.IFS('Prévisionnel annuel'!$O$4="Simulation",H38,'Prévisionnel annuel'!$O$4="Succes",H45*$B$48*$B$47)} -> 35
A32: DE | B32: {=_xlfn.IFS('Prévisionnel annuel'!$O$4="Simulation",B39,'Prévisionnel annuel'!$O$4="Succes",B46*$B$48*$B$47)} -> 35 | C32: {=_xlfn.IFS('Prévisionnel annuel'!$O$4="Simulation",C39,'Prévisionnel annuel'!$O$4="Succes",C46*$B$48*$B$47)} -> 35 | D32: {=_xlfn.IFS('Prévisionnel annuel'!$O$4="Simulation",D39,'Prévisionnel annuel'!$O$4="Succes",D46*$B$48*$B$47)} -> 35 | E32: {=_xlfn.IFS('Prévisionnel annuel'!$O$4="Simulation",E39,'Prévisionnel annuel'!$O$4="Succes",E46*$B$48*$B$47)} -> 35 | F32: {=_xlfn.IFS('Prévisionnel annuel'!$O$4="Simulation",F39,'Prévisionnel annuel'!$O$4="Succes",F46*$B$48*$B$47)} -> 35 | G32: {=_xlfn.IFS('Prévisionnel annuel'!$O$4="Simulation",G39,'Prévisionnel annuel'!$O$4="Succes",G46*$B$48*$B$47)} -> 35 | H32: {=_xlfn.IFS('Prévisionnel annuel'!$O$4="Simulation",H39,'Prévisionnel annuel'!$O$4="Succes",H46*$B$48*$B$47)} -> 35
A34: Prix moyen simu - modèle simu Leads
A35: FR | B35: 35 | C35: 35 | D35: 35 | E35: 35 | F35: 35 | G35: 35 | H35: 35
A36: ES | B36: 35 | C36: 35 | D36: 35 | E36: 35 | F36: 35 | G36: 35 | H36: 35
A37: CH | B37: 35 | C37: 35 | D37: 35 | E37: 35 | F37: 35 | G37: 35 | H37: 35
A38: BE | B38: 35 | C38: 35 | D38: 35 | E38: 35 | F38: 35 | G38: 35 | H38: 35
A39: DE | B39: 35 | C39: 35 | D39: 35 | E39: 35 | F39: 35 | G39: 35 | H39: 35
A41: Prix moyen projet - modèle succes Leads
A42: FR | B42: 6000 | C42: =B42*102% -> 6120 | D42: =C42*102% -> 6242.4 | E42: =D42*102% -> 6367.248 | F42: =E42*102% -> 6494.593 | G42: =F42*102% -> 6624.4848 | H42: =G42*102% -> 6756.9745
A43: ES | B43: 5000 | C43: =B43*102% -> 5100 | D43: =C43*102% -> 5202 | E43: =D43*102% -> 5306.04 | F43: =E43*102% -> 5412.1608 | G43: =F43*102% -> 5520.404 | H43: =G43*102% -> 5630.8121
A44: CH | B44: 15000 | C44: =B44*102% -> 15300 | D44: =C44*102% -> 15606 | E44: =D44*102% -> 15918.12 | F44: =E44*102% -> 16236.482 | G44: =F44*102% -> 16561.212 | H44: =G44*102% -> 16892.436
A45: BE | B45: 6000 | C45: =B45*102% -> 6120 | D45: =C45*102% -> 6242.4 | E45: =D45*102% -> 6367.248 | F45: =E45*102% -> 6494.593 | G45: =F45*102% -> 6624.4848 | H45: =G45*102% -> 6756.9745
A46: DE | B46: 6000 | C46: =B46*102% -> 6120 | D46: =C46*102% -> 6242.4 | E46: =D46*102% -> 6367.248 | F46: =E46*102% -> 6494.593 | G46: =F46*102% -> 6624.4848 | H46: =G46*102% -> 6756.9745
A47: Success fees | B47: 0.05
...

Sheet Ventes
C1: 2025 | J1: 2026 | V1: 2027 | AH1: 2028 | AT1: 2029 | BF1: 2030
C2: 45809 | D2: 45839 | E2: 45870 | F2: 45901 | G2: 45931 | H2: 45962 | I2: 45992 | J2: 46023 | K2: 46054 | L2: 46082 | M2: 46113 | N2: 46143 | O2: 46174 | P2: 46204 | Q2: 46235 | R2: 46266 | S2: 46296 | T2: 46327 | U2: 46357 | V2: 46388 | W2: 46419 | X2: 46447 | Y2: 46478 | Z2: 46508 | AA2: 46539 | AB2: 46569 | AC2: 46600 | AD2: 46631 | AE2: 46661 | AF2: 46692 | AG2: 46722 | AH2: 46753 | AI2: 46784 | AJ2: 46813 | AK2: 46844 | AL2: 46874 | AM2: 46905 | AN2: 46935 | AO2: 46966 | AP2: 46997 | AQ2: 47027 | AR2: 47058 | AS2: 47088 | AT2: 47119 | AU2: 47150 | AV2: 47178 | AW2: 47209 | AX2: 47239 | AY2: 47270 | AZ2: 47300 | BA2: 47331 | BB2: 47362 | BC2: 47392 | BD2: 47423 | BE2: 47453 | BF2: 47484 | BG2: 47515 | BH2: 47543 | BI2: 47574 | BJ2: 47604 | BK2: 47635 | BL2: 47665 | BM2: 47696 | BN2: 47727 | BO2: 47757 | BP2: 47788 | BQ2: 47818 | BR2: 47849 | BS2: 47880 | BT2: 47908 | BU2: 47939 | BV2: 47969 | BW2: 48000 | BX2: 48030 | BY2: 48061 | BZ2: 48092 | CA2: 48122 | CB2: 48153 | CC2: 48183
A3: REVENUS (HT) | C3: =C4+C8+C12 -> 53008.343 | D3: =D4+D8+D12 -> 54444.887 | E3: =E4+E8+E12 -> 55553.416 | F3: =F4+F8+F12 -> 56642.458 | G3: =G4+G8+G12 -> 57712.458 | H3: =H4+H8+H12 -> 58763.855 | I3: =I4+I8+I12 -> 59797.07 | J3: =J4+J8+J12 -> 63058.019 | ... CC3: =CC4+CC8+CC12 -> 1386303.1
A4: Abonnements - Optiwize Pro | C4: =C19*Hypothèses!$B$20 -> 52424.018 | D4: =D19*Hypothèses!$B$20 -> 53499.623 | E4: =E19*Hypothèses!$B$20 -> 54554.438 | F4: =F19*Hypothèses!$B$20 -> 55588.949 | G4: =G19*Hypothèses!$B$20 -> 56603.627 | H4: =H19*Hypothèses!$B$20 -> 57598.932 | I4: =I19*Hypothèses!$B$20 -> 58575.31 | J4: =J19*Hypothèses!$C$20 -> 60975.406 | K4: =K19*Hypothèses!$C$20 -> 62280.54 | L4: =L19*Hypothèses!$C$20 -> 62555.562 | M4: =M19*Hypothèses!$C$20 -> 63841.557 | N4: =N19*Hypothèses!$C$20 -> 65108.034 | O4: =O19*Hypothèses!$C$20 -> 66355.349 | P4: =P19*Hypothèses!$C$20 -> 67583.85 | Q4: =Q19*Hypothèses!$C$20 -> 69244.211 | ... U4: =U19*Hypothèses!$C$20 -> 75620.737 | V4: =V19*Hypothèses!$D$20 -> 83500.764 | W4: =W19*Hypothèses!$D$20 -> 85314.75 | X4: =X19*Hypothèses!$D$20 -> 87107.916 | Y4: =Y19*Hypothèses!$D$20 -> 88880.555 | Z4: =Z19*Hypothèses!$D$20 -> 90632.954 | AA4: =AA19*Hypothèses!$D$20 -> 92365.396 | AB4: =AB19*Hypothèses!$D$20 -> 94078.159 | AC4: =AC19*Hypothèses!$D$20 -> 96014.683 | ... AG4: =AG19*Hypothèses!$D$20 -> 103533.73 | AH4: =AH19*Hypothèses!$E$20 -> 108653 | AI4: =AI19*Hypothèses!$E$20 -> 110708.51 | AJ4: =AJ19*Hypothèses!$E$20 -> 112746.49 | AK4: =AK19*Hypothèses!$E$20 -> 114767.09 | AL4: =AL19*Hypothèses!$E$20 -> 116770.48 | AM4: =AM19*Hypothèses!$E$20 -> 118756.8 | AN4: =AN19*Hypothèses!$E$20 -> 120726.22 | AO4: =AO19*Hypothèses!$E$20 -> 122678.89 | ... AS4: =AS19*Hypothèses!$E$20 -> 130325.11 | AT4: =AT19*Hypothèses!$F$20 -> 136083.61 | AU4: =AU19*Hypothèses!$F$20 -> 138079.98 | AV4: =AV19*Hypothèses!$F$20 -> 140064.11 | AW4: =AW19*Hypothèses!$F$20 -> 142036.02 | AX4: =AX19*Hypothèses!$F$20 -> 143995.71 | AY4: =AY19*Hypothèses!$F$20 -> 145943.19 | AZ4: =AZ19*Hypothèses!$F$20 -> 147878.47 | BA4: =BA19*Hypothèses!$F$20 -> 150445.36 | ... BE4: =BE19*Hypothèses!$F$20 -> 160521.72 | BF4: =BF19*Hypothèses!$G$20 -> 173871.03 | BG4: =BG19*Hypothèses!$G$20 -> 176640.34 | BH4: =BH19*Hypothèses!$G$20 -> 181852.66 | BI4: =BI19*Hypothèses!$G$20 -> 187020.47 | BJ4: =BJ19*Hypothèses!$G$20 -> 194607.45 | BK4: =BK19*Hypothèses!$G$20 -> 204589.96 | BL4: =BL19*Hypothèses!$G$20 -> 214481.47 | BM4: =BM19*Hypothèses!$G$20 -> 239920.55 | ... BQ4: =BQ19*Hypothèses!$G$20 -> 339243.32 | BR4: =BR19*Hypothèses!$H$20 -> 365496.86 | BS4: =BS19*Hypothèses!$H$20 -> 390835.89 | BT4: =BT19*Hypothèses!$H$20 -> 415928.57 | BU4: =BU19*Hypothèses!$H$20 -> 441979.34 | BV4: =BV19*Hypothèses!$H$20 -> 467777.96 | BW4: =BW19*Hypothèses!$H$20 -> 493327.53 | BX4: =BX19*Hypothèses!$H$20 -> 522309.6 | BY4: =BY19*Hypothèses!$H$20 -> 592996.34 | ... CC4: =CC19*Hypothèses!$H$20 -> 878776.35
A5: Installateurs
A6: Bureaux d'études
A8: Pay as you go - Leads | C8: =C9+C10 -> 584.325 | D8: =D9+D10 -> 629.44238 | E8: =E9+E10 -> 675.63438 | F8: =F9+F10 -> 722.86868 | G8: =G9+G10 -> 771.11402 | H8: =H9+H10 -> 820.34007 | I8: =I9+I10 -> 870.51748 | J8: =J9+J10 -> 1190.1325 | ... CC8: =CC9+CC10 -> 474956.64
A9: Installateurs/developpeurs | C9: =(C43*Hypothèses!$B$12/12*Hypothèses!$B$28+C44*Hypothèses!$B$13/12*Hypothèses!$B$29+C45*Hypothèses!$B$14/12*Hypothèses!$B$30+C46*Hypothèses!$B$15/12*Hypothèses!$B$31+C47*Hypothèses!$B$16/12*Hypothèses!$B$32)*Hypothèses!$B$72 -> 584.325 | D9: =(D43*Hypothèses!$B$12/12*Hypothèses!$B$28+D44*Hypothèses!$B$13/12*Hypothèses!$B$29+D45*Hypothèses!$B$14/12*Hypothèses!$B$30+D46*Hypothèses!$B$15/12*Hypothèses!$B$31+D47*Hypothèses!$B$16/12*Hypothèses!$B$32)*Hypothèses!$B$72 -> 629.44238 | E9: =(E43*Hypothèses!$B$12/12*Hypothèses!$B$28+E44*Hypothèses!$B$13/12*Hypothèses!$B$29+E45*Hypothèses!$B$14/12*Hypothèses!$B$30+E46*Hypothèses!$B$15/12*Hypothèses!$B$31+E47*Hypothèses!$B$16/12*Hypothèses!$B$32)*Hypothèses!$B$72 -> 675.63438 | F9: =(F43*Hypothèses!$B$12/12*Hypothèses!$B$28+F44*Hypothèses!$B$13/12*Hypothèses!$B$29+F45*Hypothèses!$B$14/12*Hypothèses!$B$30+F46*Hypothèses!$B$15/12*Hypothèses!$B$31+F47*Hypothèses!$B$16/12*Hypothèses!$B$32)*Hypothèses!$B$72 -> 722.86868 | G9: =(G43*Hypothèses!$B$12/12*Hypothèses!$B$28+G44*Hypothèses!$B$13/12*Hypothèses!$B$29+G45*Hypothèses!$B$14/12*Hypothèses!$B$30+G46*Hypothèses!$B$15/12*Hypothèses!$B$31+G47*Hypothèses!$B$16/12*Hypothèses!$B$32)*Hypothèses!$B$72 -> 771.11402 | H9: =(H43*Hypothèses!$B$12/12*Hypothèses!$B$28+H44*Hypothèses!$B$13/12*Hypothèses!$B$29+H45*Hypothèses!$B$14/12*Hypothèses!$B$30+H46*Hypothèses!$B$15/12*Hypothèses!$B$31+H47*Hypothèses!$B$16/12*Hypothèses!$B$32)*Hypothèses!$B$72 -> 820.34007 | I9: =(I43*Hypothèses!$B$12/12*Hypothèses!$B$28+I44*Hypothèses!$B$13/12*Hypothèses!$B$29+I45*Hypothèses!$B$14/12*Hypothèses!$B$30+I46*Hypothèses!$B$15/12*Hypothèses!$B$31+I47*Hypothèses!$B$16/12*Hypothèses!$B$32)*Hypothèses!$B$72 -> 870.51748 | J9: =(J43*Hypothèses!$C$12/12*Hypothèses!$C$28+J44*Hypothèses!$C$13/12*Hypothèses!$C$29+J45*Hypothèses!$C$14/12*Hypothèses!$C$30+J46*Hypothèses!$C$15/12*Hypothèses!$C$31+J47*Hypothèses!$C$16/12*Hypothèses!$B$32)*Hypothèses!$C$72 -> 1190.1325 | K9: =(K43*Hypothèses!$C$12/12*Hypothèses!$C$28+K44*Hypothèses!$C$13/12*Hypothèses!$C$29+K45*Hypothèses!$C$14/12*Hypothèses!$C$30+K46*Hypothèses!$C$15/12*Hypothèses!$C$31+K47*Hypothèses!$C$16/12*Hypothèses!$B$32)*Hypothèses!$C$72 -> 1350.6738 | L9: =(L43*Hypothèses!$C$12/12*Hypothèses!$C$28+L44*Hypothèses!$C$13/12*Hypothèses!$C$29+L45*Hypothèses!$C$14/12*Hypothèses!$C$30+L46*Hypothèses!$C$15/12*Hypothèses!$C$31+L47*Hypothèses!$C$16/12*Hypothèses!$B$32)*Hypothèses!$C$72 -> 1492.302 | M9: =(M43*Hypothèses!$C$12/12*Hypothèses!$C$28+M44*Hypothèses!$C$13/12*Hypothèses!$C$29+M45*Hypothèses!$C$14/12*Hypothèses!$C$30+M46*Hypothèses!$C$15/12*Hypothèses!$C$31+M47*Hypothèses!$C$16/12*Hypothèses!$B$32)*Hypothèses!$C$72 -> 1661.433 | N9: =(N43*Hypothèses!$C$12/12*Hypothèses!$C$28+N44*Hypothèses!$C$13/12*Hypothèses!$C$29+N45*Hypothèses!$C$14/12*Hypothèses!$C$30+N46*Hypothèses!$C$15/12*Hypothèses!$C$31+N47*Hypothèses!$C$16/12*Hypothèses!$B$32)*Hypothèses!$C$72 -> 1835.5915 | O9: =(O43*Hypothèses!$C$12/12*Hypothèses!$C$28+O44*Hypothèses!$C$13/12*Hypothèses!$C$29+O45*Hypothèses!$C$14/12*Hypothèses!$C$30+O46*Hypothèses!$C$15/12*Hypothèses!$C$31+O47*Hypothèses!$C$16/12*Hypothèses!$B$32)*Hypothèses!$C$72 -> 2014.6615 | P9: =(P43*Hypothèses!$C$12/12*Hypothèses!$C$28+P44*Hypothèses!$C$13/12*Hypothèses!$C$29+P45*Hypothèses!$C$14/12*Hypothèses!$C$30+P46*Hypothèses!$C$15/12*Hypothèses!$C$31+P47*Hypothèses!$C$16/12*Hypothèses!$B$32)*Hypothèses!$C$72 -> 2198.5295 | Q9: =(Q43*Hypothèses!$C$12/12*Hypothèses!$C$28+Q44*Hypothèses!$C$13/12*Hypothèses!$C$29+Q45*Hypothèses!$C$14/12*Hypothèses!$C$30+Q46*Hypothèses!$C$15/12*Hypothèses!$C$31+Q47*Hypothèses!$C$16/12*Hypothèses!$B$32)*Hypothèses!$C$72 -> 2402.7112 | ... U9: =(U43*Hypothèses!$C$12/12*Hypothèses!$C$28+U44*Hypothèses!$C$13/12*Hypothèses!$C$29+U45*Hypothèses!$C$14/12*Hypothèses!$C$30+U46*Hypothèses!$C$15/12*Hypothèses!$C$31+U47*Hypothèses!$C$16/12*Hypothèses!$B$32)*Hypothèses!$C$72 -> 3279.9635 | V9: =(V43*Hypothèses!$D$12/12*Hypothèses!$D$28+V44*Hypothèses!$D$13/12*Hypothèses!$D$29+V45*Hypothèses!$D$14/12*Hypothèses!$D$30+V46*Hypothèses!$D$15/12*Hypothèses!$D$31+V47*Hypothèses!$D$16/12*Hypothèses!$D$32)*Hypothèses!$D$72 -> 5055.8398 | W9: =(W43*Hypothèses!$D$12/12*Hypothèses!$D$28+W44*Hypothèses!$D$13/12*Hypothèses!$D$29+W45*Hypothèses!$D$14/12*Hypothèses!$D$30+W46*Hypothèses!$D$15/12*Hypothèses!$D$31+W47*Hypothèses!$D$16/12*Hypothèses!$D$32)*Hypothèses!$D$72 -> 5488.5284 | X9: =(X43*Hypothèses!$D$12/12*Hypothèses!$D$28+X44*Hypothèses!$D$13/12*Hypothèses!$D$29+X45*Hypothèses!$D$14/12*Hypothèses!$D$30+X46*Hypothèses!$D$15/12*Hypothèses!$D$31+X47*Hypothèses!$D$16/12*Hypothèses!$D$32)*Hypothèses!$D$72 -> 5933.5281 | Y9: =(Y43*Hypothèses!$D$12/12*Hypothèses!$D$28+Y44*Hypothèses!$D$13/12*Hypothèses!$D$29+Y45*Hypothèses!$D$14/12*Hypothèses!$D$30+Y46*Hypothèses!$D$15/12*Hypothèses!$D$31+Y47*Hypothèses!$D$16/12*Hypothèses!$D$32)*Hypothèses!$D$72 -> 6390.6235 | Z9: =(Z43*Hypothèses!$D$12/12*Hypothèses!$D$28+Z44*Hypothèses!$D$13/12*Hypothèses!$D$29+Z45*Hypothèses!$D$14/12*Hypothèses!$D$30+Z46*Hypothèses!$D$15/12*Hypothèses!$D$31+Z47*Hypothèses!$D$16/12*Hypothèses!$D$32)*Hypothèses!$D$72 -> 6859.6034 | AA9: =(AA43*Hypothèses!$D$12/12*Hypothèses!$D$28+AA44*Hypothèses!$D$13/12*Hypothèses!$D$29+AA45*Hypothèses!$D$14/12*Hypothèses!$D$30+AA46*Hypothèses!$D$15/12*Hypothèses!$D$31+AA47*Hypothèses!$D$16/12*Hypothèses!$D$32)*Hypothèses!$D$72 -> 7340.2604 | AB9: =(AB43*Hypothèses!$D$12/12*Hypothèses!$D$28+AB44*Hypothèses!$D$13/12*Hypothèses!$D$29+AB45*Hypothèses!$D$14/12*Hypothèses!$D$30+AB46*Hypothèses!$D$15/12*Hypothèses!$D$31+AB47*Hypothèses!$D$16/12*Hypothèses!$D$32)*Hypothèses!$D$72 -> 7832.3911 | AC9: =(AC43*Hypothèses!$D$12/12*Hypothèses!$D$28+AC44*Hypothèses!$D$13/12*Hypothèses!$D$29+AC45*Hypothèses!$D$14/12*Hypothèses!$D$30+AC46*Hypothèses!$D$15/12*Hypothèses!$D$31+AC47*Hypothèses!$D$16/12*Hypothèses!$D$32)*Hypothèses!$D$72 -> 8356.9607 | ... AG9: =(AG43*Hypothèses!$D$12/12*Hypothèses!$D$28+AG44*Hypothèses!$D$13/12*Hypothèses!$D$29+AG45*Hypothèses!$D$14/12*Hypothèses!$D$30+AG46*Hypothèses!$D$15/12*Hypothèses!$D$31+AG47*Hypothèses!$D$16/12*Hypothèses!$D$32)*Hypothèses!$D$72 -> 10578.608 | AH9: =(AH43*Hypothèses!$E$12/12*Hypothèses!$E$28+AH44*Hypothèses!$E$13/12*Hypothèses!$E$29+AH45*Hypothèses!$E$14/12*Hypothèses!$E$30+AH46*Hypothèses!$E$15/12*Hypothèses!$E$31+AH47*Hypothèses!$E$16/12*Hypothèses!$E$32)*Hypothèses!$E$72 -> 17623.48 | AI9: =(AI43*Hypothèses!$E$12/12*Hypothèses!$E$28+AI44*Hypothèses!$E$13/12*Hypothèses!$E$29+AI45*Hypothèses!$E$14/12*Hypothèses!$E$30+AI46*Hypothèses!$E$15/12*Hypothèses!$E$31+AI47*Hypothèses!$E$16/12*Hypothèses!$E$32)*Hypothèses!$E$72 -> 18442.204 | AJ9: =(AJ43*Hypothèses!$E$12/12*Hypothèses!$E$28+AJ44*Hypothèses!$E$13/12*Hypothèses!$E$29+AJ45*Hypothèses!$E$14/12*Hypothèses!$E$30+AJ46*Hypothèses!$E$15/12*Hypothèses!$E$31+AJ47*Hypothèses!$E$16/12*Hypothèses!$E$32)*Hypothèses!$E$72 -> 19275.952 | AK9: =(AK43*Hypothèses!$E$12/12*Hypothèses!$E$28+AK44*Hypothèses!$E$13/12*Hypothèses!$E$29+AK45*Hypothèses!$E$14/12*Hypothèses!$E$30+AK46*Hypothèses!$E$15/12*Hypothèses!$E$31+AK47*Hypothèses!$E$16/12*Hypothèses!$E$32)*Hypothèses!$E$72 -> 20124.522 | AL9: =(AL43*Hypothèses!$E$12/12*Hypothèses!$E$28+AL44*Hypothèses!$E$13/12*Hypothèses!$E$29+AL45*Hypothèses!$E$14/12*Hypothèses!$E$30+AL46*Hypothèses!$E$15/12*Hypothèses!$E$31+AL47*Hypothèses!$E$16/12*Hypothèses!$E$32)*Hypothèses!$E$72 -> 20987.713 | AM9: =(AM43*Hypothèses!$E$12/12*Hypothèses!$E$28+AM44*Hypothèses!$E$13/12*Hypothèses!$E$29+AM45*Hypothèses!$E$14/12*Hypothèses!$E$30+AM46*Hypothèses!$E$15/12*Hypothèses!$E$31+AM47*Hypothèses!$E$16/12*Hypothèses!$E$32)*Hypothèses!$E$72 -> 21865.328 | AN9: =(AN43*Hypothèses!$E$12/12*Hypothèses!$E$28+AN44*Hypothèses!$E$13/12*Hypothèses!$E$29+AN45*Hypothèses!$E$14/12*Hypothèses!$E$30+AN46*Hypothèses!$E$15/12*Hypothèses!$E$31+AN47*Hypothèses!$E$16/12*Hypothèses!$E$32)*Hypothèses!$E$72 -> 22757.171 | AO9: =(AO43*Hypothèses!$E$12/12*Hypothèses!$E$28+AO44*Hypothèses!$E$13/12*Hypothèses!$E$29+AO45*Hypothèses!$E$14/12*Hypothèses!$E$30+AO46*Hypothèses!$E$15/12*Hypothèses!$E$31+AO47*Hypothèses!$E$16/12*Hypothèses!$E$32)*Hypothèses!$E$72 -> 23663.051 | ... AS9: =(AS43*Hypothèses!$E$12/12*Hypothèses!$E$28+AS44*Hypothèses!$E$13/12*Hypothèses!$E$29+AS45*Hypothèses!$E$14/12*Hypothèses!$E$30+AS46*Hypothèses!$E$15/12*Hypothèses!$E$31+AS47*Hypothèses!$E$16/12*Hypothèses!$E$32)*Hypothèses!$E$72 -> 27423.163 | AT9: =(AT43*Hypothèses!$F$12/12*Hypothèses!$F$28+AT44*Hypothèses!$F$13/12*Hypothèses!$F$29+AT45*Hypothèses!$F$14/12*Hypothèses!$F$30+AT46*Hypothèses!$F$15/12*Hypothèses!$F$31+AT47*Hypothèses!$F$16/12*Hypothèses!$F$32)*Hypothèses!$F$72 -> 41262.389 | AU9: =(AU43*Hypothèses!$F$12/12*Hypothèses!$F$28+AU44*Hypothèses!$F$13/12*Hypothèses!$F$29+AU45*Hypothèses!$F$14/12*Hypothèses!$F$30+AU46*Hypothèses!$F$15/12*Hypothèses!$F$31+AU47*Hypothèses!$F$16/12*Hypothèses!$F$32)*Hypothèses!$F$72 -> 42156.456 | AV9: =(AV43*Hypothèses!$F$12/12*Hypothèses!$F$28+AV44*Hypothèses!$F$13/12*Hypothèses!$F$29+AV45*Hypothèses!$F$14/12*Hypothèses!$F$30+AV46*Hypothèses!$F$15/12*Hypothèses!$F$31+AV47*Hypothèses!$F$16/12*Hypothèses!$F$32)*Hypothèses!$F$72 -> 43055.114 | AW9: =(AW43*Hypothèses!$F$12/12*Hypothèses!$F$28+AW44*Hypothèses!$F$13/12*Hypothèses!$F$29+AW45*Hypothèses!$F$14/12*Hypothèses!$F$30+AW46*Hypothèses!$F$15/12*Hypothèses!$F$31+AW47*Hypothèses!$F$16/12*Hypothèses!$F$32)*Hypothèses!$F$72 -> 43958.286 | AX9: =(AX43*Hypothèses!$F$12/12*Hypothèses!$F$28+AX44*Hypothèses!$F$13/12*Hypothèses!$F$29+AX45*Hypothèses!$F$14/12*Hypothèses!$F$30+AX46*Hypothèses!$F$15/12*Hypothèses!$F$31+AX47*Hypothèses!$F$16/12*Hypothèses!$F$32)*Hypothèses!$F$72 -> 44865.898 | AY9: =(AY43*Hypothèses!$F$12/12*Hypothèses!$F$28+AY44*Hypothèses!$F$13/12*Hypothèses!$F$29+AY45*Hypothèses!$F$14/12*Hypothèses!$F$30+AY46*Hypothèses!$F$15/12*Hypothèses!$F$31+AY47*Hypothèses!$F$16/12*Hypothèses!$F$32)*Hypothèses!$F$72 -> 45777.875 | AZ9: =(AZ43*Hypothèses!$F$12/12*Hypothèses!$F$28+AZ44*Hypothèses!$F$13/12*Hypothèses!$F$29+AZ45*Hypothèses!$F$14/12*Hypothèses!$F$30+AZ46*Hypothèses!$F$15/12*Hypothèses!$F$31+AZ47*Hypothèses!$F$16/12*Hypothèses!$F$32)*Hypothèses!$F$72 -> 46694.144 | BA9: =(BA43*Hypothèses!$F$12/12*Hypothèses!$F$28+BA44*Hypothèses!$F$13/12*Hypothèses!$F$29+BA45*Hypothèses!$F$14/12*Hypothèses!$F$30+BA46*Hypothèses!$F$15/12*Hypothèses!$F$31+BA47*Hypothèses!$F$16/12*Hypothèses!$F$32)*Hypothèses!$F$72 -> 47819.269 | ... BE9: =(BE43*Hypothèses!$F$12/12*Hypothèses!$F$28+BE44*Hypothèses!$F$13/12*Hypothèses!$F$29+BE45*Hypothèses!$F$14/12*Hypothèses!$F$30+BE46*Hypothèses!$F$15/12*Hypothèses!$F$31+BE47*Hypothèses!$F$16/12*Hypothèses!$F$32)*Hypothèses!$F$72 -> 52364.74 | BF9: =(BF43*Hypothèses!$G$12/12*Hypothèses!$G$28+BF44*Hypothèses!$G$13/12*Hypothèses!$G$29+BF45*Hypothèses!$G$14/12*Hypothèses!$G$30+BF46*Hypothèses!$G$15/12*Hypothèses!$G$31+BF47*Hypothèses!$G$16/12*Hypothèses!$G$32)*Hypothèses!$G$72 -> 78976.399 | BG9: =(BG43*Hypothèses!$G$12/12*Hypothèses!$G$28+BG44*Hypothèses!$G$13/12*Hypothèses!$G$29+BG45*Hypothèses!$G$14/12*Hypothèses!$G$30+BG46*Hypothèses!$G$15/12*Hypothèses!$G$31+BG47*Hypothèses!$G$16/12*Hypothèses!$G$32)*Hypothèses!$G$72 -> 80234.286 | BH9: =(BH43*Hypothèses!$G$12/12*Hypothèses!$G$28+BH44*Hypothèses!$G$13/12*Hypothèses!$G$29+BH45*Hypothèses!$G$14/12*Hypothèses!$G$30+BH46*Hypothèses!$G$15/12*Hypothèses!$G$31+BH47*Hypothèses!$G$16/12*Hypothèses!$G$32)*Hypothèses!$G$72 -> 82601.85 | BI9: =(BI43*Hypothèses!$G$12/12*Hypothèses!$G$28+BI44*Hypothèses!$G$13/12*Hypothèses!$G$29+BI45*Hypothèses!$G$14/12*Hypothèses!$G$30+BI46*Hypothèses!$G$15/12*Hypothèses!$G$31+BI47*Hypothèses!$G$16/12*Hypothèses!$G$32)*Hypothèses!$G$72 -> 84949.193 | BJ9: =(BJ43*Hypothèses!$G$12/12*Hypothèses!$G$28+BJ44*Hypothèses!$G$13/12*Hypothèses!$G$29+BJ45*Hypothèses!$G$14/12*Hypothèses!$G$30+BJ46*Hypothèses!$G$15/12*Hypothèses!$G$31+BJ47*Hypothèses!$G$16/12*Hypothèses!$G$32)*Hypothèses!$G$72 -> 88395.382 | BK9: =(BK43*Hypothèses!$G$12/12*Hypothèses!$G$28+BK44*Hypothèses!$G$13/12*Hypothèses!$G$29+BK45*Hypothèses!$G$14/12*Hypothèses!$G$30+BK46*Hypothèses!$G$15/12*Hypothèses!$G$31+BK47*Hypothèses!$G$16/12*Hypothèses!$G$32)*Hypothèses!$G$72 -> 92929.676 | BL9: =(BL43*Hypothèses!$G$12/12*Hypothèses!$G$28+BL44*Hypothèses!$G$13/12*Hypothèses!$G$29+BL45*Hypothèses!$G$14/12*Hypothèses!$G$30+BL46*Hypothèses!$G$15/12*Hypothèses!$G$31+BL47*Hypothèses!$G$16/12*Hypothèses!$G$32)*Hypothèses!$G$72 -> 97422.638 | BM9: =(BM43*Hypothèses!$G$12/12*Hypothèses!$G$28+BM44*Hypothèses!$G$13/12*Hypothèses!$G$29+BM45*Hypothèses!$G$14/12*Hypothèses!$G$30+BM46*Hypothèses!$G$15/12*Hypothèses!$G$31+BM47*Hypothèses!$G$16/12*Hypothèses!$G$32)*Hypothèses!$G$72 -> 107000.8 | ... BQ9: =(BQ43*Hypothèses!$G$12/12*Hypothèses!$G$28+BQ44*Hypothèses!$G$13/12*Hypothèses!$G$29+BQ45*Hypothèses!$G$14/12*Hypothèses!$G$30+BQ46*Hypothèses!$G$15/12*Hypothèses!$G$31+BQ47*Hypothèses!$G$16/12*Hypothèses!$G$32)*Hypothèses!$G$72 -> 144405.05 | BR9: =(BR43*Hypothèses!$H$12/12*Hypothèses!$H$28+BR44*Hypothèses!$H$13/12*Hypothèses!$H$29+BR45*Hypothèses!$H$14/12*Hypothèses!$H$30+BR46*Hypothèses!$H$15/12*Hypothèses!$H$31+BR47*Hypothèses!$H$16/12*Hypothèses!$H$32)*Hypothèses!$H$72 -> 209224.2 | BS9: =(BS43*Hypothèses!$H$12/12*Hypothèses!$H$28+BS44*Hypothèses!$H$13/12*Hypothèses!$H$29+BS45*Hypothèses!$H$14/12*Hypothèses!$H$30+BS46*Hypothèses!$H$15/12*Hypothèses!$H$31+BS47*Hypothèses!$H$16/12*Hypothèses!$H$32)*Hypothèses!$H$72 -> 222287.49 | BT9: =(BT43*Hypothèses!$H$12/12*Hypothèses!$H$28+BT44*Hypothèses!$H$13/12*Hypothèses!$H$29+BT45*Hypothèses!$H$14/12*Hypothèses!$H$30+BT46*Hypothèses!$H$15/12*Hypothèses!$H$31+BT47*Hypothèses!$H$16/12*Hypothèses!$H$32)*Hypothèses!$H$72 -> 235224.58 | BU9: =(BU43*Hypothèses!$H$12/12*Hypothèses!$H$28+BU44*Hypothèses!$H$13/12*Hypothèses!$H$29+BU45*Hypothèses!$H$14/12*Hypothèses!$H$30+BU46*Hypothèses!$H$15/12*Hypothèses!$H$31+BU47*Hypothèses!$H$16/12*Hypothèses!$H$32)*Hypothèses!$H$72 -> 248799.43 | BV9: =(BV43*Hypothèses!$H$12/12*Hypothèses!$H$28+BV44*Hypothèses!$H$13/12*Hypothèses!$H$29+BV45*Hypothèses!$H$14/12*Hypothèses!$H$30+BV46*Hypothèses!$H$15/12*Hypothèses!$H$31+BV47*Hypothèses!$H$16/12*Hypothèses!$H$32)*Hypothèses!$H$72 -> 262243.39 | BW9: =(BW43*Hypothèses!$H$12/12*Hypothèses!$H$28+BW44*Hypothèses!$H$13/12*Hypothèses!$H$29+BW45*Hypothèses!$H$14/12*Hypothèses!$H$30+BW46*Hypothèses!$H$15/12*Hypothèses!$H$31+BW47*Hypothèses!$H$16/12*Hypothèses!$H$32)*Hypothèses!$H$72 -> 275558.06 | BX9: =(BX43*Hypothèses!$H$12/12*Hypothèses!$H$28+BX44*Hypothèses!$H$13/12*Hypothèses!$H$29+BX45*Hypothèses!$H$14/12*Hypothèses!$H$30+BX46*Hypothèses!$H$15/12*Hypothèses!$H$31+BX47*Hypothèses!$H$16/12*Hypothèses!$H$32)*Hypothèses!$H$72 -> 291032.24 | BY9: =(BY43*Hypothèses!$H$12/12*Hypothèses!$H$28+BY44*Hypothèses!$H$13/12*Hypothèses!$H$29+BY45*Hypothèses!$H$14/12*Hypothèses!$H$30+BY46*Hypothèses!$H$15/12*Hypothèses!$H$31+BY47*Hypothèses!$H$16/12*Hypothèses!$H$32)*Hypothèses!$H$72 -> 327318.56 | ... CC9: =(CC43*Hypothèses!$H$12/12*Hypothèses!$H$28+CC44*Hypothèses!$H$13/12*Hypothèses!$H$29+CC45*Hypothèses!$H$14/12*Hypothèses!$H$30+CC46*Hypothèses!$H$15/12*Hypothèses!$H$31+CC47*Hypothèses!$H$16/12*Hypothèses!$H$32)*Hypothèses!$H$72 -> 474956.64
A12: Prestation | C12: =SUM(C13:C14) -> 0 | D12: =SUM(D13:D14) -> 315.82164 | E12: =SUM(E13:E14) -> 323.34398 | F12: =SUM(F13:F14) -> 330.64017 | G12: =SUM(G13:G14) -> 337.71733 | H12: =SUM(H13:H14) -> 344.58235 | I12: =SUM(I13:I14) -> 351.24187 | J12: =SUM(J13:J14) -> 892.48048 | ... CC12: =SUM(CC13:CC14) -> 32570.151
A13: Installations Optiwize Pro | D13: =(D19-C19)*Hypothèses!$B$74 -> 0 | E13: =(E19-D19)*Hypothèses!$B$74 -> 0 | F13: =(F19-E19)*Hypothèses!$B$74 -> 0 | G13: =(G19-F19)*Hypothèses!$B$74 -> 0 | H13: =(H19-G19)*Hypothèses!$B$74 -> 0 | I13: =(I19-H19)*Hypothèses!$B$74 -> 0 | J13: =(J19-I19)*Hypothèses!$B$74 -> 0 | K13: =(K19-J19)*Hypothèses!$B$74 -> 0 | ... CC13: =(CC19-CB19)*Hypothèses!$B$74 -> 0
A14: Installations Leads | D14: =(D42-C42)*Hypothèses!$B$75 -> 315.82164 | E14: =(E42-D42)*Hypothèses!$B$75 -> 323.34398 | F14: =(F42-E42)*Hypothèses!$B$75 -> 330.64017 | G14: =(G42-F42)*Hypothèses!$B$75 -> 337.71733 | H14: =(H42-G42)*Hypothèses!$B$75 -> 344.58235 | I14: =(I42-H42)*Hypothèses!$B$75 -> 351.24187 | J14: =(J42-I42)*Hypothèses!$B$75 -> 892.48048 | K14: =(K42-J42)*Hypothèses!$B$75 -> 942.38076 | ... CC14: =(CC42-CB42)*Hypothèses!$B$75 -> 32570.151
A16: MILESTONES | V16: Lancement Espagne | AH16: Lancement Suisse | AM16: Leads v2
A19: # CLIENTS | C19: =C20+C51 -> 159 | D19: =D20+D51 -> 162.26227 | E19: =E20+E51 -> 165.46148 | F19: =F20+F51 -> 168.59911 | G19: =G20+G51 -> 171.67659 | H19: =H20+H51 -> 174.69531 | I19: =I20+I51 -> 177.65663 | J19: =J20+J51 -> 181.04575 | ... CC19: =CC20+CC51 -> 2128.5565
A20: Installateurs/developpeurs | C20: =C21+C28+C35 -> 111.3 | D20: =D21+D28+D35 -> 113.58359 | E20: =E21+E28+E35 -> 115.82304 | F20: =F21+F28+F35 -> 118.01938 | G20: =G21+G28+G35 -> 120.17361 | H20: =H21+H28+H35 -> 122.28672 | I20: =I21+I28+I35 -> 124.35964 | J20: =J21+J28+J35 -> 126.73202 | ... CC20: =CC21+CC28+CC35 -> 1308.2322
A21: Optiwize Pro - Premium | C21: =C22+C23+C24 -> 35 | D21: =D22+D23+D24 -> 35.697549 | E21: =E22+E23+E24 -> 36.388123 | F21: =F22+F23+F24 -> 37.071791 | G21: =G22+G23+G24 -> 37.748622 | H21: =H22+H23+H24 -> 38.418685 | I21: =I22+I23+I24 -> 39.082047 | J21: =J22+J23+J24 -> 39.959787 | ... CC21: =CC22+CC23+CC24 -> 575.83379
A22: dt FR | C22: 35 | D22: =C22*(1-'Annexe G Evolution Portefeuill'!$C20)+C$86*'Annexe B Plan commercial'!$B5*Hypothèses!$B$54 -> 35.697549 | E22: =D22*(1-'Annexe G Evolution Portefeuill'!$C20)+D$86*'Annexe B Plan commercial'!$B5*Hypothèses!$B$54 -> 36.388123 | F22: =E22*(1-'Annexe G Evolution Portefeuill'!$C20)+E$86*'Annexe B Plan commercial'!$B5*Hypothèses!$B$54 -> 37.071791 | G22: =F22*(1-'Annexe G Evolution Portefeuill'!$C20)+F$86*'Annexe B Plan commercial'!$B5*Hypothèses!$B$54 -> 37.748622 | H22: =G22*(1-'Annexe G Evolution Portefeuill'!$C20)+G$86*'Annexe B Plan commercial'!$B5*Hypothèses!$B$54 -> 38.418685 | I22: =H22*(1-'Annexe G Evolution Portefeuill'!$C20)+H$86*'Annexe B Plan commercial'!$B5*Hypothèses!$B$54 -> 39.082047 | J22: =I22*(1-'Annexe G Evolution Portefeuill'!$D20)+I$86*'Annexe B Plan commercial'!$C5*Hypothèses!$C$54 -> 39.959787 | K22: =J22*(1-'Annexe G Evolution Portefeuill'!$D20)+J$86*'Annexe B Plan commercial'!$C5*Hypothèses!$C$54 -> 40.924104 | L22: =K22*(1-'Annexe G Evolution Portefeuill'!$D20)+K$86*'Annexe B Plan commercial'!$C5*Hypothèses!$C$54 -> 41.355705 | M22: =L22*(1-'Annexe G Evolution Portefeuill'!$D20)+L$86*'Annexe B Plan commercial'!$C5*Hypothèses!$C$54 -> 42.308854 | N22: =M22*(1-'Annexe G Evolution Portefeuill'!$D20)+M$86*'Annexe B Plan commercial'!$C5*Hypothèses!$C$54 -> 43.254378 | O22: =N22*(1-'Annexe G Evolution Portefeuill'!$D20)+N$86*'Annexe B Plan commercial'!$C5*Hypothèses!$C$54 -> 44.192337 | P22: =O22*(1-'Annexe G Evolution Portefeuill'!$D20)+O$86*'Annexe B Plan commercial'!$C5*Hypothèses!$C$54 -> 45.122793 | Q22: =P22*(1-'Annexe G Evolution Portefeuill'!$D20)+P$86*'Annexe B Plan commercial'!$C5*Hypothèses!$C$54 -> 46.2798 | ... U22: =T22*(1-'Annexe G Evolution Portefeuill'!$D20)+T$86*'Annexe B Plan commercial'!$C5*Hypothèses!$C$54 -> 50.816004 | V22: =U22*(1-'Annexe G Evolution Portefeuill'!$E20)+U$86*'Annexe B Plan commercial'!$D5*Hypothèses!$D$54 -> 52.332695 | W22: =V22*(1-'Annexe G Evolution Portefeuill'!$E20)+V$86*'Annexe B Plan commercial'!$D5*Hypothèses!$D$54 -> 53.840286 | X22: =W22*(1-'Annexe G Evolution Portefeuill'!$E20)+W$86*'Annexe B Plan commercial'!$D5*Hypothèses!$D$54 -> 55.338831 | Y22: =X22*(1-'Annexe G Evolution Portefeuill'!$E20)+X$86*'Annexe B Plan commercial'!$D5*Hypothèses!$D$54 -> 56.828385 | Z22: =Y22*(1-'Annexe G Evolution Portefeuill'!$E20)+Y$86*'Annexe B Plan commercial'!$D5*Hypothèses!$D$54 -> 58.309001 | AA22: =Z22*(1-'Annexe G Evolution Portefeuill'!$E20)+Z$86*'Annexe B Plan commercial'!$D5*Hypothèses!$D$54 -> 59.780734 | AB22: =AA22*(1-'Annexe G Evolution Portefeuill'!$E20)+AA$86*'Annexe B Plan commercial'!$D5*Hypothèses!$D$54 -> 61.243637 | AC22: =AB22*(1-'Annexe G Evolution Portefeuill'!$E20)+AB$86*'Annexe B Plan commercial'!$D5*Hypothèses!$D$54 -> 62.838158 | ... AG22: =AF22*(1-'Annexe G Evolution Portefeuill'!$E20)+AF$86*'Annexe B Plan commercial'!$D5*Hypothèses!$D$54 -> 69.121147 | AH22: =AG22*(1-'Annexe G Evolution Portefeuill'!$F20)+AG$86*'Annexe B Plan commercial'!$E5*Hypothèses!$E$54 -> 71.064522 | AI22: =AH22*(1-'Annexe G Evolution Portefeuill'!$F20)+AH$86*'Annexe B Plan commercial'!$E5*Hypothèses!$E$54 -> 72.99818 | AJ22: =AI22*(1-'Annexe G Evolution Portefeuill'!$F20)+AI$86*'Annexe B Plan commercial'!$E5*Hypothèses!$E$54 -> 74.92217 | AK22: =AJ22*(1-'Annexe G Evolution Portefeuill'!$F20)+AJ$86*'Annexe B Plan commercial'!$E5*Hypothèses!$E$54 -> 76.83654 | AL22: =AK22*(1-'Annexe G Evolution Portefeuill'!$F20)+AK$86*'Annexe B Plan commercial'!$E5*Hypothèses!$E$54 -> 78.741338 | AM22: =AL22*(1-'Annexe G Evolution Portefeuill'!$F20)+AL$86*'Annexe B Plan commercial'!$E5*Hypothèses!$E$54 -> 80.636613 | AN22: =AM22*(1-'Annexe G Evolution Portefeuill'!$F20)+AM$86*'Annexe B Plan commercial'!$E5*Hypothèses!$E$54 -> 82.52241 | AO22: =AN22*(1-'Annexe G Evolution Portefeuill'!$F20)+AN$86*'Annexe B Plan commercial'!$E5*Hypothèses!$E$54 -> 84.398779 | ... AS22: =AR22*(1-'Annexe G Evolution Portefeuill'!$F20)+AR$86*'Annexe B Plan commercial'!$E5*Hypothèses!$E$54 -> 91.810904 | AT22: =AS22*(1-'Annexe G Evolution Portefeuill'!$G20)+AS$86*'Annexe B Plan commercial'!$F5*Hypothèses!$F$54 -> 93.967828 | AU22: =AT22*(1-'Annexe G Evolution Portefeuill'!$G20)+AT$86*'Annexe B Plan commercial'!$F5*Hypothèses!$F$54 -> 96.113967 | AV22: =AU22*(1-'Annexe G Evolution Portefeuill'!$G20)+AU$86*'Annexe B Plan commercial'!$F5*Hypothèses!$F$54 -> 98.249375 | AW22: =AV22*(1-'Annexe G Evolution Portefeuill'!$G20)+AV$86*'Annexe B Plan commercial'!$F5*Hypothèses!$F$54 -> 100.37411 | AX22: =AW22*(1-'Annexe G Evolution Portefeuill'!$G20)+AW$86*'Annexe B Plan commercial'!$F5*Hypothèses!$F$54 -> 102.48821 | AY22: =AX22*(1-'Annexe G Evolution Portefeuill'!$G20)+AX$86*'Annexe B Plan commercial'!$F5*Hypothèses!$F$54 -> 104.59175 | AZ22: =AY22*(1-'Annexe G Evolution Portefeuill'!$G20)+AY$86*'Annexe B Plan commercial'!$F5*Hypothèses!$F$54 -> 106.68477 | BA22: =AZ22*(1-'Annexe G Evolution Portefeuill'!$G20)+AZ$86*'Annexe B Plan commercial'!$F5*Hypothèses!$F$54 -> 109.23531 | ... BE22: =BD22*(1-'Annexe G Evolution Portefeuill'!$G20)+BD$86*'Annexe B Plan commercial'!$F5*Hypothèses!$F$54 -> 119.3106 | BF22: =BE22*(1-'Annexe G Evolution Portefeuill'!$H20)+BE$86*'Annexe B Plan commercial'!$G5*Hypothèses!$G$54 -> 122.18351 | BG22: =BF22*(1-'Annexe G Evolution Portefeuill'!$H20)+BF$86*'Annexe B Plan commercial'!$G5*Hypothèses!$G$54 -> 125.04205 | BH22: =BG22*(1-'Annexe G Evolution Portefeuill'!$H20)+BG$86*'Annexe B Plan commercial'!$G5*Hypothèses!$G$54 -> 128.83131 | BI22: =BH22*(1-'Annexe G Evolution Portefeuill'!$H20)+BH$86*'Annexe B Plan commercial'!$G5*Hypothèses!$G$54 -> 132.60161 | BJ22: =BI22*(1-'Annexe G Evolution Portefeuill'!$H20)+BI$86*'Annexe B Plan commercial'!$G5*Hypothèses!$G$54 -> 138.24307 | BK22: =BJ22*(1-'Annexe G Evolution Portefeuill'!$H20)+BJ$86*'Annexe B Plan commercial'!$G5*Hypothèses!$G$54 -> 145.74631 | BL22: =BK22*(1-'Annexe G Evolution Portefeuill'!$H20)+BK$86*'Annexe B Plan commercial'!$G5*Hypothèses!$G$54 -> 153.21205 | BM22: =BL22*(1-'Annexe G Evolution Portefeuill'!$H20)+BL$86*'Annexe B Plan commercial'!$G5*Hypothèses!$G$54 -> 160.95099 | ... BQ22: =BP22*(1-'Annexe G Evolution Portefeuill'!$H20)+BP$86*'Annexe B Plan commercial'!$G5*Hypothèses!$G$54 -> 191.52173 | BR22: =BQ22*(1-'Annexe G Evolution Portefeuill'!$I20)+BQ$86*'Annexe B Plan commercial'!$H5*Hypothèses!$H$54 -> 199.06912 | BS22: =BR22*(1-'Annexe G Evolution Portefeuill'!$I20)+BR$86*'Annexe B Plan commercial'!$H5*Hypothèses!$H$54 -> 206.57877 | BT22: =BS22*(1-'Annexe G Evolution Portefeuill'!$I20)+BS$86*'Annexe B Plan commercial'!$H5*Hypothèses!$H$54 -> 214.05088 | BU22: =BT22*(1-'Annexe G Evolution Portefeuill'!$I20)+BT$86*'Annexe B Plan commercial'!$H5*Hypothèses!$H$54 -> 221.48563 | BV22: =BU22*(1-'Annexe G Evolution Portefeuill'!$I20)+BU$86*'Annexe B Plan commercial'!$H5*Hypothèses!$H$54 -> 228.8832 | BW22: =BV22*(1-'Annexe G Evolution Portefeuill'!$I20)+BV$86*'Annexe B Plan commercial'!$H5*Hypothèses!$H$54 -> 236.24378 | BX22: =BW22*(1-'Annexe G Evolution Portefeuill'!$I20)+BW$86*'Annexe B Plan commercial'!$H5*Hypothèses!$H$54 -> 243.56756 | BY22: =BX22*(1-'Annexe G Evolution Portefeuill'!$I20)+BX$86*'Annexe B Plan commercial'!$H5*Hypothèses!$H$54 -> 259.27853 | ... CC22: =CB22*(1-'Annexe G Evolution Portefeuill'!$I20)+CB$86*'Annexe B Plan commercial'!$H5*Hypothèses!$H$54 -> 325.09251
A23: dt ES | C23: 0 | D23: =C$23*(1-'Annexe G Evolution Portefeuill'!$C20)+C$87*'Annexe B Plan commercial'!$B$11*Hypothèses!$B$55 -> 0 | E23: =D$23*(1-'Annexe G Evolution Portefeuill'!$C20)+D$87*'Annexe B Plan commercial'!$B$11*Hypothèses!$B$55 -> 0 | F23: =E$23*(1-'Annexe G Evolution Portefeuill'!$C20)+E$87*'Annexe B Plan commercial'!$B$11*Hypothèses!$B$55 -> 0 | G23: =F$23*(1-'Annexe G Evolution Portefeuill'!$C20)+F$87*'Annexe B Plan commercial'!$B$11*Hypothèses!$B$55 -> 0 | H23: =G$23*(1-'Annexe G Evolution Portefeuill'!$C20)+G$87*'Annexe B Plan commercial'!$B$11*Hypothèses!$B$55 -> 0 | I23: =H$23*(1-'Annexe G Evolution Portefeuill'!$C20)+H$87*'Annexe B Plan commercial'!$B$11*Hypothèses!$B$55 -> 0 | J23: =I$23*(1-'Annexe G Evolution Portefeuill'!$D20)+I$87*'Annexe B Plan commercial'!$C$11*Hypothèses!$C$55 -> 0 | K23: =J$23*(1-'Annexe G Evolution Portefeuill'!$D20)+J$87*'Annexe B Plan commercial'!$C$11*Hypothèses!$C$55 -> 0 | L23: =K$23*(1-'Annexe G Evolution Portefeuill'!$D20)+K$87*'Annexe B Plan commercial'!$C$11*Hypothèses!$C$55 -> 0 | M23: =L$23*(1-'Annexe G Evolution Portefeuill'!$D20)+L$87*'Annexe B Plan commercial'!$C$11*Hypothèses!$C$55 -> 0 | N23: =M$23*(1-'Annexe G Evolution Portefeuill'!$D20)+M$87*'Annexe B Plan commercial'!$C$11*Hypothèses!$C$55 -> 0 | O23: =N$23*(1-'Annexe G Evolution Portefeuill'!$D20)+N$87*'Annexe B Plan commercial'!$C$11*Hypothèses!$C$55 -> 0 | P23: =O$23*(1-'Annexe G Evolution Portefeuill'!$D20)+O$87*'Annexe B Plan commercial'!$C$11*Hypothèses!$C$55 -> 0 | Q23: =P$23*(1-'Annexe G Evolution Portefeuill'!$D20)+P$87*'Annexe B Plan commercial'!$C$11*Hypothèses!$C$55 -> 0 | ... U23: =T$23*(1-'Annexe G Evolution Portefeuill'!$D20)+T$87*'Annexe B Plan commercial'!$C$11*Hypothèses!$C$55 -> 0 | V23: =U$23*(1-'Annexe G Evolution Portefeuill'!$E$20)+U$87*'Annexe B Plan commercial'!$D$11*Hypothèses!$D$55 -> 0 | W23: =V$23*(1-'Annexe G Evolution Portefeuill'!$E$20)+V$87*'Annexe B Plan commercial'!$D$11*Hypothèses!$D$55 -> 0 | X23: =W$23*(1-'Annexe G Evolution Portefeuill'!$E$20)+W$87*'Annexe B Plan commercial'!$D$11*Hypothèses!$D$55 -> 0 | Y23: =X$23*(1-'Annexe G Evolution Portefeuill'!$E$20)+X$87*'Annexe B Plan commercial'!$D$11*Hypothèses!$D$55 -> 0 | Z23: =Y$23*(1-'Annexe G Evolution Portefeuill'!$E$20)+Y$87*'Annexe B Plan commercial'!$D$11*Hypothèses!$D$55 -> 0 | AA23: =Z$23*(1-'Annexe G Evolution Portefeuill'!$E$20)+Z$87*'Annexe B Plan commercial'!$D$11*Hypothèses!$D$55 -> 0 | AB23: =AA$23*(1-'Annexe G Evolution Portefeuill'!$E$20)+AA$87*'Annexe B Plan commercial'!$D$11*Hypothèses!$D$55 -> 0 | AC23: =AB$23*(1-'Annexe G Evolution Portefeuill'!$E$20)+AB$87*'Annexe B Plan commercial'!$D$11*Hypothèses!$D$55 -> 0 | ... AG23: =AF$23*(1-'Annexe G Evolution Portefeuill'!$E$20)+AF$87*'Annexe B Plan commercial'!$D$11*Hypothèses!$D$55 -> 0 | AH23: =AG$23*(1-'Annexe G Evolution Portefeuill'!$F$20)+AG$87*'Annexe B Plan commercial'!$E$11*Hypothèses!$E$55 -> 0 | AI23: =AH$23*(1-'Annexe G Evolution Portefeuill'!$F$20)+AH$87*'Annexe B Plan commercial'!$E$11*Hypothèses!$E$55 -> 0 | AJ23: =AI$23*(1-'Annexe G Evolution Portefeuill'!$F$20)+AI$87*'Annexe B Plan commercial'!$E$11*Hypothèses!$E$55 -> 0 | AK23: =AJ$23*(1-'Annexe G Evolution Portefeuill'!$F$20)+AJ$87*'Annexe B Plan commercial'!$E$11*Hypothèses!$E$55 -> 0 | AL23: =AK$23*(1-'Annexe G Evolution Portefeuill'!$F$20)+AK$87*'Annexe B Plan commercial'!$E$11*Hypothèses!$E$55 -> 0 | AM23: =AL$23*(1-'Annexe G Evolution Portefeuill'!$F$20)+AL$87*'Annexe B Plan commercial'!$E$11*Hypothèses!$E$55 -> 0 | AN23: =AM$23*(1-'Annexe G Evolution Portefeuill'!$F$20)+AM$87*'Annexe B Plan commercial'!$E$11*Hypothèses!$E$55 -> 0 | AO23: =AN$23*(1-'Annexe G Evolution Portefeuill'!$F$20)+AN$87*'Annexe B Plan commercial'!$E$11*Hypothèses!$E$55 -> 0 | ... AS23: =AR$23*(1-'Annexe G Evolution Portefeuill'!$F$20)+AR$87*'Annexe B Plan commercial'!$E$11*Hypothèses!$E$55 -> 0 | AT23: =AS$23*(1-'Annexe G Evolution Portefeuill'!$G$20)+AS$87*'Annexe B Plan commercial'!$F$11*Hypothèses!$F$55 -> 0 | AU23: =AT$23*(1-'Annexe G Evolution Portefeuill'!$G$20)+AT$87*'Annexe B Plan commercial'!$F$11*Hypothèses!$F$55 -> 0 | AV23: =AU$23*(1-'Annexe G Evolution Portefeuill'!$G$20)+AU$87*'Annexe B Plan commercial'!$F$11*Hypothèses!$F$55 -> 0 | AW23: =AV$23*(1-'Annexe G Evolution Portefeuill'!$G$20)+AV$87*'Annexe B Plan commercial'!$F$11*Hypothèses!$F$55 -> 0 | AX23: =AW$23*(1-'Annexe G Evolution Portefeuill'!$G$20)+AW$87*'Annexe B Plan commercial'!$F$11*Hypothèses!$F$55 -> 0 | AY23: =AX$23*(1-'Annexe G Evolution Portefeuill'!$G$20)+AX$87*'Annexe B Plan commercial'!$F$11*Hypothèses!$F$55 -> 0 | AZ23: =AY$23*(1-'Annexe G Evolution Portefeuill'!$G$20)+AY$87*'Annexe B Plan commercial'!$F$11*Hypothèses!$F$55 -> 0 | BA23: =AZ$23*(1-'Annexe G Evolution Portefeuill'!$G$20)+AZ$87*'Annexe B Plan commercial'!$F$11*Hypothèses!$F$55 -> 0 | ... BE23: =BD$23*(1-'Annexe G Evolution Portefeuill'!$G$20)+BD$87*'Annexe B Plan commercial'!$F$11*Hypothèses!$F$55 -> 0 | BF23: =BE$23*(1-'Annexe G Evolution Portefeuill'!$H$20)+BE$87*'Annexe B Plan commercial'!$G$11*Hypothèses!$G$55 -> 0 | BG23: =BF$23*(1-'Annexe G Evolution Portefeuill'!$H$20)+BF$87*'Annexe B Plan commercial'!$G$11*Hypothèses!$G$55 -> 0 | BH23: =BG$23*(1-'Annexe G Evolution Portefeuill'!$H$20)+BG$87*'Annexe B Plan commercial'!$G$11*Hypothèses!$G$55 -> 0.84 | BI23: =BH$23*(1-'Annexe G Evolution Portefeuill'!$H$20)+BH$87*'Annexe B Plan commercial'!$G$11*Hypothèses!$G$55 -> 1.6758 | BJ23: =BI$23*(1-'Annexe G Evolution Portefeuill'!$H$20)+BI$87*'Annexe B Plan commercial'!$G$11*Hypothèses!$G$55 -> 2.507421 | BK23: =BJ$23*(1-'Annexe G Evolution Portefeuill'!$H$20)+BJ$87*'Annexe B Plan commercial'!$G$11*Hypothèses!$G$55 -> 3.3348839 | BL23: =BK$23*(1-'Annexe G Evolution Portefeuill'!$H$20)+BK$87*'Annexe B Plan commercial'!$G$11*Hypothèses!$G$55 -> 4.1582095 | BM23: =BL$23*(1-'Annexe G Evolution Portefeuill'!$H$20)+BL$87*'Annexe B Plan commercial'!$G$11*Hypothèses!$G$55 -> 12.398388 | ... BQ23: =BP$23*(1-'Annexe G Evolution Portefeuill'!$H$20)+BP$87*'Annexe B Plan commercial'!$G$11*Hypothèses!$G$55 -> 44.949149 | BR23: =BQ$23*(1-'Annexe G Evolution Portefeuill'!$I$20)+BQ$87*'Annexe B Plan commercial'!$G$11*Hypothèses!$G$55 -> 52.985373 | BS23: =BR$23*(1-'Annexe G Evolution Portefeuill'!$I$20)+BR$87*'Annexe B Plan commercial'!$G$11*Hypothèses!$G$55 -> 61.821416 | BT23: =BS$23*(1-'Annexe G Evolution Portefeuill'!$I$20)+BS$87*'Annexe B Plan commercial'!$G$11*Hypothèses!$G$55 -> 70.613279 | BU23: =BT$23*(1-'Annexe G Evolution Portefeuill'!$I$20)+BT$87*'Annexe B Plan commercial'!$G$11*Hypothèses!$G$55 -> 79.361182 | BV23: =BU$23*(1-'Annexe G Evolution Portefeuill'!$I$20)+BU$87*'Annexe B Plan commercial'!$G$11*Hypothèses!$G$55 -> 88.065346 | BW23: =BV$23*(1-'Annexe G Evolution Portefeuill'!$I$20)+BV$87*'Annexe B Plan commercial'!$G$11*Hypothèses!$G$55 -> 96.725989 | BX23: =BW$23*(1-'Annexe G Evolution Portefeuill'!$I$20)+BW$87*'Annexe B Plan commercial'!$G$11*Hypothèses!$G$55 -> 107.02333 | BY23: =BX$23*(1-'Annexe G Evolution Portefeuill'!$I$20)+BX$87*'Annexe B Plan commercial'!$G$11*Hypothèses!$G$55 -> 120.54511 | ... CC23: =CB$23*(1-'Annexe G Evolution Portefeuill'!$I$20)+CB$87*'Annexe B Plan commercial'!$G$11*Hypothèses!$G$55 -> 177.3111
