Workbook

Sheet Plan strategique
A1: BUSINESS PLAN SEED - MEDTECH / DISPOSITIF MEDICAL
A2: Template FounderAI - Cellules jaunes a remplir
A4: IDENTITE
A5: Nom | B5: NeuraSense
A6: Secteur | B6: MedTech - Dispositif de monitoring neurologique portable
A7: Date creation | B7: Janvier 2025
A8: Fondateurs | B8: Dr. Sophie Laurent (CEO, neurologue), Marc Belin (CTO, ingenieur biomed)
A9: Localisation | B9: Strasbourg, France
A10: Stade | B10: Prototype fonctionnel, etude pre-clinique en cours
A12: PARCOURS REGLEMENTAIRE
A13: Phase actuelle | B13: Prototype + tests pre-cliniques | C13: Y1
A14: Etude clinique pilote | B14: 30 patients, 2 centres hospitaliers | C14: Y2
A15: Marquage CE (classe IIa) | B15: Dossier technique + organisme notifie | C15: Y2-Y3
A16: Etude clinique pivot | B16: 150 patients, multi-centres | C16: Y3
A17: Mise sur le marche France | B17: Remboursement LPPR en cours | C17: Y4
A18: Extension Europe | B18: Marquage CE etendu | C18: Y5
A20: MODELE ECONOMIQUE
A21: Revenu 1 | B21: Vente de dispositifs (DM) aux hopitaux - 5 000 euro/unite
A22: Revenu 2 | B22: Consommables/capteurs recurrents - 200 euro/patient/mois
A23: Revenu 3 | B23: Licence logiciel analyse IA - SaaS 500 euro/mois/service

Sheet Hypotheses
A1: HYPOTHESES - MEDTECH (5 ANS)
A3: REVENUS
B4: Y1 | C4: Y2 | D4: Y3 | E4: Y4 | F4: Y5 | G4: Y6
A5: Dispositifs vendus (annee) | B5: 0 | C5: 0 | D5: 0 | E5: 20 | F5: 60 | G5: 100
A6: Prix moyen DM (euro) | B6: 0 | C6: 0 | D6: 0 | E6: 5000 | F6: 4800 | G6: 5200
A7: CA Dispositifs | B7: =B5*B6 -> 0 | C7: =C5*C6 -> 0 | D7: =D5*D6 -> 0 | E7: =E5*E6 -> 100000 | F7: =F5*F6 -> 288000 | G7: =G5*G6 -> 520000
A8: Patients sous monitoring (cumul) | B8: 0 | C8: 0 | D8: 0 | E8: 100 | F8: 400 | G8: 900
A9: Revenu consommable/patient/mois | B9: 0 | C9: 0 | D9: 0 | E9: 200 | F9: 180 | G9: 170
A10: CA Consommables | B10: =B8*B9*12 -> 0 | C10: =C8*C9*12 -> 0 | D10: =D8*D9*12 -> 0 | E10: =E8*E9*12 -> 240000 | F10: =F8*F9*12 -> 864000 | G10: =G8*G9*12 -> 1836000
A11: Licences logiciel actives | B11: 0 | C11: 0 | D11: 0 | E11: 5 | F11: 15 | G11: 30
A12: Prix licence/mois (euro) | B12: 0 | C12: 0 | D12: 0 | E12: 500 | F12: 500 | G12: 500
A13: Revenus etudes cliniques sponsor. | B13: 0 | C13: 50000 | D13: 80000 | E13: 30000 | F13: 0 | G13: 0
A14: Grants / prix recherche | B14: 30000 | C14: 40000 | D14: 20000 | E14: 0 | F14: 0 | G14: 0
A15: CA Licences SaaS | B15: =B11*B12*12 -> 0 | C15: =C11*C12*12 -> 0 | D15: =D11*D12*12 -> 0 | E15: =E11*E12*12 -> 30000 | F15: =F11*F12*12 -> 90000 | G15: =G11*G12*12 -> 180000
A16: CA TOTAL | B16: =B7+B10+B15+B13+B14 -> 30000 | C16: =C7+C10+C15+C13+C14 -> 90000 | D16: =D7+D10+D15+D13+D14 -> 100000 | E16: =E7+E10+E15+E13+E14 -> 400000 | F16: =F7+F10+F15+F13+F14 -> 1242000 | G16: =G7+G10+G15+G13+G14 -> 2536000
A18: DEPENSES R&D & REGLEMENTAIRE
B19: Y1 | C19: Y2 | D19: Y3 | E19: Y4 | F19: Y5 | G19: Y6
A20: Personnel R&D | B20: 200000 | C20: 350000 | D20: 450000 | E20: 300000 | F20: 250000 | G20: 200000
A21: Materiaux prototypage | B21: 50000 | C21: 40000 | D21: 30000 | E21: 20000 | F21: 10000 | G21: 8000
A22: Sous-traitance R&D | B22: 30000 | C22: 50000 | D22: 40000 | E22: 20000 | F22: 15000 | G22: 10000
A23: Etudes cliniques | B23: 0 | C23: 120000 | D23: 250000 | E23: 80000 | F23: 0 | G23: 0
A24: Affaires reglementaires | B24: 20000 | C24: 50000 | D24: 80000 | E24: 40000 | F24: 20000 | G24: 15000
A25: Propriete intellectuelle | B25: 25000 | C25: 30000 | D25: 20000 | E25: 15000 | F25: 15000 | G25: 10000
A26: Equipements labo / tests | B26: 40000 | C26: 30000 | D26: 20000 | E26: 10000 | F26: 5000 | G26: 3000
A27: Total R&D + reglementaire | B27: =SUM(B20:B26) -> 365000 | C27: =SUM(C20:C26) -> 670000 | D27: =SUM(D20:D26) -> 890000 | E27: =SUM(E20:E26) -> 485000 | F27: =SUM(F20:F26) -> 315000 | G27: =SUM(G20:G26) -> 246000
A29: FINANCEMENT NON-DILUTIF
B30: Y1 | C30: Y2 | D30: Y3 | E30: Y4 | F30: Y5 | G30: Y6
A31: CIR (30% auto) | B31: =ROUND(B27*0.3,0) -> 109500 | C31: =ROUND(C27*0.3,0) -> 201000 | D31: =ROUND(D27*0.3,0) -> 267000 | E31: =ROUND(E27*0.3,0) -> 145500 | F31: =ROUND(F27*0.3,0) -> 94500 | G31: =ROUND(G27*0.3,0) -> 73800
A32: BPI (aide innovation / deeptech) | B32: 80000 | C32: 150000 | D32: 100000 | E32: 0 | F32: 0 | G32: 0
A33: ADEME / ANR / region | B33: 30000 | C33: 50000 | D33: 40000 | E33: 0 | F33: 0 | G33: 0
A34: Europe (EIC, Horizon) | B34: 0 | C34: 0 | D34: 300000 | E34: 0 | F34: 0 | G34: 0
A35: Concours / fondations | B35: 20000 | C35: 30000 | D35: 0 | E35: 0 | F35: 0 | G35: 0
A36: Total non-dilutif | B36: =SUM(B31:B35) -> 239500 | C36: =SUM(C31:C35) -> 431000 | D36: =SUM(D31:D35) -> 707000 | E36: =SUM(E31:E35) -> 145500 | F36: =SUM(F31:F35) -> 94500 | G36: =SUM(G31:G35) -> 73800
A37: Cout R&D net | B37: =B27-B36 -> 125500 | C37: =C27-C36 -> 239000 | D37: =D27-D36 -> 183000 | E37: =E27-E36 -> 339500 | F37: =F27-F36 -> 220500 | G37: =G27-G36 -> 172200
A39: COUTS FIXES HORS R&D
A40: Poste | B40: Y1/mois | C40: Y2/mois | D40: Y3/mois | E40: Y4/mois | F40: Y5/mois | G40: Y6
A41: Locaux | B41: 500 | C41: 800 | D41: 1500 | E41: 2500 | F41: 4000 | G41: 5000
A42: Outils & abonnements | B42: 200 | C42: 300 | D42: 500 | E42: 700 | F42: 1000 | G42: 1200
A43: Comptabilite / juridique | B43: 400 | C43: 600 | D43: 800 | E43: 1000 | F43: 1500 | G43: 1800
A44: Qualite & conformite | B44: 200 | C44: 400 | D44: 600 | E44: 800 | F44: 1000 | G44: 1200
...

Sheet Revenus
A1: REVENUS - MEDTECH
B3: Y1 | C3: Y2 | D3: Y3 | E3: Y4 | F3: Y5 | G3: Y6
A4: CA Dispositifs | B4: =Hypotheses!B7 -> 0 | C4: =Hypotheses!C7 -> 0 | D4: =Hypotheses!D7 -> 0 | E4: =Hypotheses!E7 -> 100000 | F4: =Hypotheses!F7 -> 288000 | G4: =Hypotheses!G7 -> 520000
A5: CA Consommables | B5: =Hypotheses!B10 -> 0 | C5: =Hypotheses!C10 -> 0 | D5: =Hypotheses!D10 -> 0 | E5: =Hypotheses!E10 -> 240000 | F5: =Hypotheses!F10 -> 864000 | G5: =Hypotheses!G10 -> 1836000
A6: CA Licences SaaS | B6: =Hypotheses!B15 -> 0 | C6: =Hypotheses!C15 -> 0 | D6: =Hypotheses!D15 -> 0 | E6: =Hypotheses!E15 -> 30000 | F6: =Hypotheses!F15 -> 90000 | G6: =Hypotheses!G15 -> 180000
A7: Etudes cliniques | B7: =Hypotheses!B13 -> 0 | C7: =Hypotheses!C13 -> 50000 | D7: =Hypotheses!D13 -> 80000 | E7: =Hypotheses!E13 -> 30000 | F7: =Hypotheses!F13 -> 0 | G7: =Hypotheses!G13 -> 0
A8: Grants / prix | B8: =Hypotheses!B14 -> 30000 | C8: =Hypotheses!C14 -> 40000 | D8: =Hypotheses!D14 -> 20000 | E8: =Hypotheses!E14 -> 0 | F8: =Hypotheses!F14 -> 0 | G8: =Hypotheses!G14 -> 0
A9: CA TOTAL | B9: =SUM(B4:B8) -> 30000 | C9: =SUM(C4:C8) -> 90000 | D9: =SUM(D4:D8) -> 100000 | E9: =SUM(E4:E8) -> 400000 | F9: =SUM(F4:F8) -> 1242000 | G9: =SUM(G4:G8) -> 2536000
A11: Aides non-dilutif | B11: =Hypotheses!B36 -> 239500 | C11: =Hypotheses!C36 -> 431000 | D11: =Hypotheses!D36 -> 707000 | E11: =Hypotheses!E36 -> 145500 | F11: =Hypotheses!F36 -> 94500 | G11: =Hypotheses!G36 -> 73800
A12: Total ressources | B12: =B9+B11 -> 269500 | C12: =C9+C11 -> 521000 | D12: =D9+D11 -> 807000 | E12: =E9+E11 -> 545500 | F12: =F9+F11 -> 1336500 | G12: =G9+G11 -> 2609800

Sheet Couts & PL
A1: COUTS & RESULTAT
B3: Y1 | C3: Y2 | D3: Y3 | E3: Y4 | F3: Y5 | G3: Y6
A4: CA Total | B4: =Revenus!B9 -> 30000 | C4: =Revenus!C9 -> 90000 | D4: =Revenus!D9 -> 100000 | E4: =Revenus!E9 -> 400000 | F4: =Revenus!F9 -> 1242000 | G4: =Revenus!G9 -> 2536000
A5: COGS (fabrication DM) | B5: 0 | C5: 0 | D5: 0 | E5: 40000 | F5: 120000 | G5: 200000
A6: Marge brute | B6: =B4-B5 -> 30000 | C6: =C4-C5 -> 90000 | D6: =D4-D5 -> 100000 | E6: =E4-E5 -> 360000 | F6: =F4-F5 -> 1122000 | G6: =G4-G5 -> 2336000
A8: R&D + reglementaire | B8: =-Hypotheses!B27 -> -365000 | C8: =-Hypotheses!C27 -> -670000 | D8: =-Hypotheses!D27 -> -890000 | E8: =-Hypotheses!E27 -> -485000 | F8: =-Hypotheses!F27 -> -315000 | G8: =-Hypotheses!G27 -> -246000
A9: OPEX hors R&D | B9: =-Hypotheses!B48 -> -20400 | C9: =-Hypotheses!C48 -> -34800 | D9: =-Hypotheses!D48 -> -62400 | E9: =-Hypotheses!E48 -> -109200 | F9: =-Hypotheses!F48 -> -168000 | G9: =-Hypotheses!G48 -> -216000
A10: Masse sal hors R&D | B10: =-ABS(Hypotheses!B62) -> 0 | C10: =-ABS(Hypotheses!C62) -> -170375 | D10: =-ABS(Hypotheses!D62) -> -233450 | E10: =-ABS(Hypotheses!E62) -> -300150 | F10: =-ABS(Hypotheses!F62) -> -300150 | G10: =-ABS(Hypotheses!G62) -> -300150
A12: EBITDA avant aides | B12: =B6+B8+B9+B10 -> -355400 | C12: =C6+C8+C9+C10 -> -785175 | D12: =D6+D8+D9+D10 -> -1085850 | E12: =E6+E8+E9+E10 -> -534350 | F12: =F6+F8+F9+F10 -> 338850 | G12: =G6+G8+G9+G10 -> 1573850
A13: Financement non-dilutif | B13: =Hypotheses!B36 -> 239500 | C13: =Hypotheses!C36 -> 431000 | D13: =Hypotheses!D36 -> 707000 | E13: =Hypotheses!E36 -> 145500 | F13: =Hypotheses!F36 -> 94500 | G13: =Hypotheses!G36 -> 73800
A14: Resultat net apres aides | B14: =B12+B13 -> -115900 | C14: =C12+C13 -> -354175 | D14: =D12+D13 -> -378850 | E14: =E12+E13 -> -388850 | F14: =F12+F13 -> 433350 | G14: =G12+G13 -> 1647650

Sheet Tresorerie
A1: TRESORERIE
B3: Y1 | C3: Y2 | D3: Y3 | E3: Y4 | F3: Y5 | G3: Y6
A4: Tresorerie debut | B4: =Hypotheses!B70 -> 1340000 | C4: =B12 -> 2554100 | D4: =C12 -> 2179925 | E4: =D12 -> 1771075 | F4: =E12 -> 1357225 | G4: =F12 -> 1775575
A5: CA | B5: =Revenus!B9 -> 30000 | C5: =Revenus!C9 -> 90000 | D5: =Revenus!D9 -> 100000 | E5: =Revenus!E9 -> 400000 | F5: =Revenus!F9 -> 1242000 | G5: =Revenus!G9 -> 2536000
A6: Aides non-dilutif | B6: =Hypotheses!B36 -> 239500 | C6: =Hypotheses!C36 -> 431000 | D6: =Hypotheses!D36 -> 707000 | E6: =Hypotheses!E36 -> 145500 | F6: =Hypotheses!F36 -> 94500 | G6: =Hypotheses!G36 -> 73800
A7: Decaissements | B7: ='Couts & PL'!B12-'Couts & PL'!B4 -> -385400 | C7: ='Couts & PL'!C12-'Couts & PL'!C4 -> -875175 | D7: ='Couts & PL'!D12-'Couts & PL'!D4 -> -1185850 | E7: ='Couts & PL'!E12-'Couts & PL'!E4 -> -934350 | F7: ='Couts & PL'!F12-'Couts & PL'!F4 -> -903150 | G7: ='Couts & PL'!G12-'Couts & PL'!G4 -> -962150
A8: CAPEX hors R&D | B8: -10000 | C8: -20000 | D8: -30000 | E8: -25000 | F8: -15000 | G8: -10000
A9: Financement dilutif | B9: 1340000 | C9: 0 | D9: 0 | E9: 0 | F9: 0 | G9: 0
A10: Remboursements | B10: 0 | C10: 0 | D10: 0 | E10: 0 | F10: 0 | G10: 0
A11: Flux net | B11: =SUM(B5:B10) -> 1214100 | C11: =SUM(C5:C10) -> -374175 | D11: =SUM(D5:D10) -> -408850 | E11: =SUM(E5:E10) -> -413850 | F11: =SUM(F5:F10) -> 418350 | G11: =SUM(G5:G10) -> 1637650
A12: Tresorerie fin | B12: =B4+B11 -> 2554100 | C12: =C4+C11 -> 2179925 | D12: =D4+D11 -> 1771075 | E12: =E4+E11 -> 1357225 | F12: =F4+F11 -> 1775575 | G12: =G4+G11 -> 3413225
A14: Burn rate mensuel | B14: =IF(B11<0,-B11/12,0) -> 0 | C14: =IF(C11<0,-C11/12,0) -> 31181.25 | D14: =IF(D11<0,-D11/12,0) -> 34070.833 | E14: =IF(E11<0,-E11/12,0) -> 34487.5 | F14: =IF(F11<0,-F11/12,0) -> 0 | G14: =IF(G11<0,-G11/12,0) -> 0
A15: Runway (mois) | B15: =IF(B14>0,B4/B14,99) -> 99 | C15: =IF(C14>0,C4/C14,99) -> 81.911405 | D15: =IF(D14>0,D4/D14,99) -> 63.982145 | E15: =IF(E14>0,E4/E14,99) -> 51.354114 | F15: =IF(F14>0,F4/F14,99) -> 99 | G15: =IF(G14>0,G4/G14,99) -> 99

Sheet KPIs
A1: KPIs - MEDTECH
A3: INDICATEUR | B3: Y1 | C3: Y2 | D3: Y3 | E3: Y4 | F3: Y5 | G3: Y6
A4: R&D & REGLEMENTAIRE
A5: Depenses R&D + reg | B5: =Hypotheses!B27 -> 365000 | C5: =Hypotheses!C27 -> 670000 | D5: =Hypotheses!D27 -> 890000 | E5: =Hypotheses!E27 -> 485000 | F5: =Hypotheses!F27 -> 315000 | G5: =Hypotheses!G27 -> 246000
A6: Aides non-dilutif | B6: =Hypotheses!B36 -> 239500 | C6: =Hypotheses!C36 -> 431000 | D6: =Hypotheses!D36 -> 707000 | E6: =Hypotheses!E36 -> 145500 | F6: =Hypotheses!F36 -> 94500 | G6: =Hypotheses!G36 -> 73800
A7: Cout R&D net | B7: =Hypotheses!B37 -> 125500 | C7: =Hypotheses!C37 -> 239000 | D7: =Hypotheses!D37 -> 183000 | E7: =Hypotheses!E37 -> 339500 | F7: =Hypotheses!F37 -> 220500 | G7: =Hypotheses!G37 -> 172200
A8: % R&D financee | B8: =IF(Hypotheses!B27>0,Hypotheses!B36/Hypotheses!B27,0) -> 0.65616438 | C8: =IF(Hypotheses!C27>0,Hypotheses!C36/Hypotheses!C27,0) -> 0.64328358 | D8: =IF(Hypotheses!D27>0,Hypotheses!D36/Hypotheses!D27,0) -> 0.79438202 | E8: =IF(Hypotheses!E27>0,Hypotheses!E36/Hypotheses!E27,0) -> 0.3 | F8: =IF(Hypotheses!F27>0,Hypotheses!F36/Hypotheses!F27,0) -> 0.3 | G8: =IF(Hypotheses!G27>0,Hypotheses!G36/Hypotheses!G27,0) -> 0.3
A10: COMMERCIAL
A11: CA total | B11: =Revenus!B9 -> 30000 | C11: =Revenus!C9 -> 90000 | D11: =Revenus!D9 -> 100000 | E11: =Revenus!E9 -> 400000 | F11: =Revenus!F9 -> 1242000 | G11: =Revenus!G9 -> 2536000
A12: DM vendus (annee) | B12: =Hypotheses!B5 -> 0 | C12: =Hypotheses!C5 -> 0 | D12: =Hypotheses!D5 -> 0 | E12: =Hypotheses!E5 -> 20 | F12: =Hypotheses!F5 -> 60 | G12: =Hypotheses!G5 -> 100
A13: Patients monitoring | B13: =Hypotheses!B8 -> 0 | C13: =Hypotheses!C8 -> 0 | D13: =Hypotheses!D8 -> 0 | E13: =Hypotheses!E8 -> 100 | F13: =Hypotheses!F8 -> 400 | G13: =Hypotheses!G8 -> 900
A14: CA recurrent (%) | B14: =IF(Revenus!B9>0,(Revenus!B5+Revenus!B6)/Revenus!B9,0) -> 0 | C14: =IF(Revenus!C9>0,(Revenus!C5+Revenus!C6)/Revenus!C9,0) -> 0 | D14: =IF(Revenus!D9>0,(Revenus!D5+Revenus!D6)/Revenus!D9,0) -> 0 | E14: =IF(Revenus!E9>0,(Revenus!E5+Revenus!E6)/Revenus!E9,0) -> 0.675 | F14: =IF(Revenus!F9>0,(Revenus!F5+Revenus!F6)/Revenus!F9,0) -> 0.76811594 | G14: =IF(Revenus!G9>0,(Revenus!G5+Revenus!G6)/Revenus!G9,0) -> 0.79495268
A16: RENTABILITE
A17: EBITDA avant aides | B17: ='Couts & PL'!B12 -> -355400 | C17: ='Couts & PL'!C12 -> -785175 | D17: ='Couts & PL'!D12 -> -1085850 | E17: ='Couts & PL'!E12 -> -534350 | F17: ='Couts & PL'!F12 -> 338850 | G17: ='Couts & PL'!G12 -> 1573850
A18: Resultat apres aides | B18: ='Couts & PL'!B14 -> -115900 | C18: ='Couts & PL'!C14 -> -354175 | D18: ='Couts & PL'!D14 -> -378850 | E18: ='Couts & PL'!E14 -> -388850 | F18: ='Couts & PL'!F14 -> 433350 | G18: ='Couts & PL'!G14 -> 1647650
A19: Tresorerie | B19: =Tresorerie!B12 -> 2554100 | C19: =Tresorerie!C12 -> 2179925 | D19: =Tresorerie!D12 -> 1771075 | E19: =Tresorerie!E12 -> 1357225 | F19: =Tresorerie!F12 -> 1775575 | G19: =Tresorerie!G12 -> 3413225
A20: Runway (mois) | B20: =Tresorerie!B15 -> 99 | C20: =Tresorerie!C15 -> 81.911405 | D20: =Tresorerie!D15 -> 63.982145 | E20: =Tresorerie!E15 -> 51.354114 | F20: =Tresorerie!F15 -> 99 | G20: =Tresorerie!G15 -> 99

Sheet Mode d'emploi
A1: MODE D'EMPLOI - BP MEDTECH
A4: Template pour dispositifs medicaux, diagnostics in vitro, e-sante, biotech.
A5: Horizon 5 ans avec parcours reglementaire integre.
A7: SPECIFICITES : Etudes cliniques budgetees, marquage CE planifie,
A8: 3 sources de revenus (dispositifs + consommables + SaaS), CIR auto 30%.
A10: Remplir dans cet ordre : Plan strategique > Hypotheses > Verifier resultats
A12: En MedTech le cash est critique. Un dispositif medical met 3-5 ans
A13: avant de generer des revenus significatifs. Planifiez vos levees tot.
