Workbook

Sheet Plan stratégique
A1: BUSINESS PLAN SEED — MODÈLE SERVICES / PRESTATIONS
A2: Template FounderAI. Cellules jaunes a remplir (exemples gris a ecraser)
A4: IDENTITE DU PROJET
A5: Nom de la startup | B5: DataPilot Consulting
A6: Secteur | B6: Conseil en data & IA pour PME
A7: Date de creation | B7: Fevrier 2026
A8: Fondateur(s) | B8: Karim Belkadi (CEO), Julie Chen (Lead Data)
A9: Localisation | B9: Bordeaux, France
A10: Stade actuel | B10: 3 missions realisees, 2 clients recurrents
A12: PROBLEME & SOLUTION
A13: Probleme resolu | B13: Les PME industrielles n'exploitent pas leurs donnees car les cabinets de conseil data sont trop chers (1 500 euro/j) et inadaptes
A14: Solution proposee | B14: Missions de conseil data clé en main pour PME : audit, dashboarding, IA predictive, a partir de 800 euro/jour
A15: Proposition de valeur | B15: Prix 2x inferieur aux grands cabinets, specialisation PME industrielles, livrables operationnels en 4 semaines
A17: MARCHE & MODELE
A18: TAM | B18: 8 Mds euro - Conseil en data & IA en Europe
A19: SAM | B19: 600 M euro - PME industrielles francaises
A20: SOM (3 ans) | B20: 1,5 M euro - 120 missions/an a 12K euro de panier moyen
A21: Client ideal | B21: DAF ou DG de PME industrielle, 50-500 salaries, Nouvelle-Aquitaine puis France | C21: Qui achete
A22: Type de prestation | B22: Missions au forfait (80%) + regie/TJM (20%) | C22: Forfait / Regie / Mixte
A24: MILESTONES 18 MOIS
A25: M1-M3 | B25: 5 missions realisees, 40K euro CA, process standardises
A26: M4-M6 | B26: 10 missions, 90K euro CA cumulé, 1er recrutement consultant
A27: M7-M12 | B27: 30 missions, 300K euro CA, 2 consultants, offres packagées
A28: M13-M18 | B28: 60 missions, 700K euro CA cumulé, 3 consultants, recurrence 40%

Sheet Hypotheses
A1: HYPOTHESES — MODELE SERVICES
A2: Cellules jaunes = vos hypotheses. Le reste se calcule automatiquement.
A4: CAPACITE & TARIFICATION
B5: Annee 1 | C5: Annee 2 | D5: Annee 3 | E5: Notes
A6: Consultants (ETP) | B6: 1.5 | C6: 3 | D6: 5 | E6: Fondateurs + recrutes
A7: Jours ouvrables / an / consultant | B7: 218 | C7: 218 | D7: 218 | E7: 365 - WE - conges - feries
A8: Taux d'occupation cible | B8: 0.6 | C8: 0.7 | D8: 0.75 | E8: % du temps facturable
A9: Jours facturables / an (calcule) | B9: =ROUND(B6*B7*B8,0) -> 196 | C9: =ROUND(C6*C7*C8,0) -> 458 | D9: =ROUND(D6*D7*D8,0) -> 818
A10: TJM moyen (euro HT) | B10: 800 | C10: 850 | D10: 900 | E10: Taux journalier moyen
A11: Panier moyen mission (euro) | B11: 8000 | C11: 10000 | D11: 12000 | E11: TJM x jours/mission
A12: Duree moyenne mission (jours) | B12: 10 | C12: 12 | D12: 13
A13: Missions / an (calcule) | B13: =ROUND(B9/B12,0) -> 20 | C13: =ROUND(C9/C12,0) -> 38 | D13: =ROUND(D9/D12,0) -> 63
A14: Taux de recurrence clients | B14: 0.25 | C14: 0.35 | D14: 0.45 | E14: % clients qui reviennent
A16: ACQUISITION CLIENTS
B17: Annee 1 | C17: Annee 2 | D17: Annee 3 | E17: Notes
A18: Nouveaux clients / an | B18: 10 | C18: 25 | D18: 45 | E18: Hors recurrence
A19: Cout acquisition client (CAC) euro | B19: 200 | C19: 150 | D19: 120 | E19: Temps + marketing
A20: Clients actifs fin d'annee (calcule) | B20: =B18 -> 10 | C20: =ROUND(B20*C14+C18,0) -> 29 | D20: =ROUND(C20*D14+D18,0) -> 58
A22: COUTS VARIABLES
A23: Poste | B23: % du CA ou euro/mission | E23: Notes
A24: Sous-traitance / freelances (% CA) | B24: 0.15 | E24: Missions sous-traitees
A25: Deplacements (euro/mission) | B25: 150 | E25: Transport, hebergement
A26: Outils & licences projet (euro/mission) | B26: 50 | E26: Licences temporaires
A27: Frais de paiement (% CA) | B27: 0.015 | E27: Virement / prelevement
A29: COUTS FIXES MENSUELS
A30: Poste | B30: Annee 1 /mois | C30: Annee 2 /mois | D30: Annee 3 /mois | E30: Notes
A31: Loyer / coworking | B31: 0 | C31: 400 | D31: 800
A32: Abonnements outils | B32: 100 | C32: 250 | D32: 400 | E32: CRM, analytics, compta
A33: Comptabilite / juridique | B33: 200 | C33: 350 | D33: 500
A34: Marketing & reseau | B34: 200 | C34: 800 | D34: 1500 | E34: Events, LinkedIn, contenu
A35: Assurances RC Pro | B35: 100 | C35: 150 | D35: 250 | E35: Obligatoire en conseil
A36: Divers | B36: 100 | C36: 200 | D36: 400
A37: Total OPEX / an | B37: =SUM(B31:B36)*12 -> 8400 | C37: =SUM(C31:C36)*12 -> 25800 | D37: =SUM(D31:D36)*12 -> 46200
A39: EQUIPE & SALAIRES
A40: Poste | B40: Mois entree | C40: Brut/an (euro) | E40: Notes
A41: Fondateur 1 | B41: 1 | C41: 0 | E41: Pas de salaire Y1
A42: Fondateur 2 / Associe | B42: 1 | C42: 0
A43: Consultant junior 1 | B43: 6 | C43: 32000
A44: Consultant junior 2 | B44: 14 | C44: 34000
A45: Office manager / admin | B45: 18 | C45: 28000
...

Sheet Revenus
A1: PROJECTIONS DE REVENUS — SERVICES
B4: Annee 1 | C4: Annee 2 | D4: Annee 3 | E4: Notes
A5: PRESTATIONS AU FORFAIT
A6: Missions (nombre) | B6: =ROUND(Hypotheses!B13*0.8,0) -> 16 | C6: =ROUND(Hypotheses!C13*0.8,0) -> 30 | D6: =ROUND(Hypotheses!D13*0.8,0) -> 50 | E6: 80% du total
A7: Panier moyen forfait (euro) | B7: =Hypotheses!B11 -> 8000 | C7: =Hypotheses!C11 -> 10000 | D7: =Hypotheses!D11 -> 12000
A8: CA Forfait | B8: =B6*B7 -> 128000 | C8: =C6*C7 -> 300000 | D8: =D6*D7 -> 600000
A10: PRESTATIONS EN REGIE (TJM)
A11: Jours en regie | B11: =ROUND(Hypotheses!B9*0.2,0) -> 39 | C11: =ROUND(Hypotheses!C9*0.2,0) -> 92 | D11: =ROUND(Hypotheses!D9*0.2,0) -> 164 | E11: 20% du temps facturable
A12: TJM moyen (euro) | B12: =Hypotheses!B10 -> 800 | C12: =Hypotheses!C10 -> 850 | D12: =Hypotheses!D10 -> 900
A13: CA Regie | B13: =B11*B12 -> 31200 | C13: =C11*C12 -> 78200 | D13: =D11*D12 -> 147600
A15: CA TOTAL | B15: =B8+B13 -> 159200 | C15: =C8+C13 -> 378200 | D15: =D8+D13 -> 747600
A17: RECAPITULATIF
A18: CA / consultant / an (euro) | B18: =IF(Hypotheses!B6>0,B15/Hypotheses!B6,0) -> 106133.33 | C18: =IF(Hypotheses!C6>0,C15/Hypotheses!C6,0) -> 126066.67 | D18: =IF(Hypotheses!D6>0,D15/Hypotheses!D6,0) -> 149520
A19: Croissance CA (%) | B19: ="-" -> - | C19: =IF(B15>0,(C15-B15)/B15,0) -> 1.3756281 | D19: =IF(C15>0,(D15-C15)/C15,0) -> 0.97673189

Sheet Couts & P&L
A1: COUTS & COMPTE DE RESULTAT
B3: Annee 1 | C3: Annee 2 | D3: Annee 3 | E3: Notes
A4: COUTS VARIABLES
A5: Sous-traitance | B5: =-Revenus!B15*Hypotheses!B24 -> -23880 | C5: =-Revenus!C15*Hypotheses!B24 -> -56730 | D5: =-Revenus!D15*Hypotheses!B24 -> -112140 | E5: % CA
A6: Deplacements | B6: =-Hypotheses!B25*Hypotheses!B13 -> -3000 | C6: =-Hypotheses!B25*Hypotheses!C13 -> -5700 | D6: =-Hypotheses!B25*Hypotheses!D13 -> -9450
A7: Outils & licences projet | B7: =-Hypotheses!B26*Hypotheses!B13 -> -1000 | C7: =-Hypotheses!B26*Hypotheses!C13 -> -1900 | D7: =-Hypotheses!B26*Hypotheses!D13 -> -3150
A8: Frais de paiement | B8: =-Revenus!B15*Hypotheses!B27 -> -2388 | C8: =-Revenus!C15*Hypotheses!B27 -> -5673 | D8: =-Revenus!D15*Hypotheses!B27 -> -11214
A9: Total couts variables | B9: =SUM(B5:B8) -> -30268 | C9: =SUM(C5:C8) -> -70003 | D9: =SUM(D5:D8) -> -135954
A11: COUTS FIXES & SALAIRES
A12: OPEX annuel | B12: =-ABS(Hypotheses!B37) -> -8400 | C12: =-ABS(Hypotheses!C37) -> -25800 | D12: =-ABS(Hypotheses!D37) -> -46200
A13: Masse salariale chargee | B13: =-ABS(Hypotheses!B51) -> -40116.667 | C13: =-ABS(Hypotheses!C51) -> -172550 | D13: =-ABS(Hypotheses!D51) -> -249400
A14: Total couts fixes + salaires | B14: =B12+B13 -> -48516.667 | C14: =C12+C13 -> -198350 | D14: =D12+D13 -> -295600
A16: COMPTE DE RESULTAT
B17: Annee 1 | C17: Annee 2 | D17: Annee 3
A18: Chiffre d'affaires | B18: =Revenus!B15 -> 159200 | C18: =Revenus!C15 -> 378200 | D18: =Revenus!D15 -> 747600
A19: Couts variables | B19: =B9 -> -30268 | C19: =C9 -> -70003 | D19: =D9 -> -135954
A20: Marge brute | B20: =B18+B19 -> 128932 | C20: =C18+C19 -> 308197 | D20: =D18+D19 -> 611646
A21: % Marge brute | B21: =IF(B18=0,0,B20/B18) -> 0.80987437 | C21: =IF(C18=0,0,C20/C18) -> 0.81490481 | D21: =IF(D18=0,0,D20/D18) -> 0.81814607
A22: Couts fixes + salaires | B22: =B14 -> -48516.667 | C22: =C14 -> -198350 | D22: =D14 -> -295600
A24: EBITDA | B24: =B20+B22 -> 80415.333 | C24: =C20+C22 -> 109847 | D24: =D20+D22 -> 316046
A25: % Marge EBITDA | B25: =IF(B18=0,0,B24/B18) -> 0.50512144 | C25: =IF(C18=0,0,C24/C18) -> 0.29044685 | D25: =IF(D18=0,0,D24/D18) -> 0.42274746

Sheet Tresorerie
A1: PLAN DE TRESORERIE
B3: Annee 1 | C3: Annee 2 | D3: Annee 3
A4: Tresorerie debut | B4: =Hypotheses!B59 -> 10000 | C4: =B10 -> 99415.333 | D4: =C10 -> 206262.33
A5: Encaissements | B5: =Revenus!B15 -> 159200 | C5: =Revenus!C15 -> 378200 | D5: =Revenus!D15 -> 747600
A6: Decaissements | B6: ='Couts & P&L'!B24-'Couts & P&L'!B18 -> -78784.667 | C6: ='Couts & P&L'!C24-'Couts & P&L'!C18 -> -268353 | D6: ='Couts & P&L'!D24-'Couts & P&L'!D18 -> -431554
A7: CAPEX | B7: -1000 | C7: -3000 | D7: -5000
A8: Apports financement | B8: =Hypotheses!B59 -> 10000 | C8: 0 | D8: 0
A9: Flux net | B9: =B5+B6+B7+B8 -> 89415.333 | C9: =C5+C6+C7+C8 -> 106847 | D9: =D5+D6+D7+D8 -> 311046
A10: Tresorerie fin | B10: =B4+B9 -> 99415.333 | C10: =C4+C9 -> 206262.33 | D10: =D4+D9 -> 517308.33
A12: METRIQUES
A13: Burn rate mensuel | B13: =IF(B9<0,-B9/12,0) -> 0 | C13: =IF(C9<0,-C9/12,0) -> 0 | D13: =IF(D9<0,-D9/12,0) -> 0
A14: Runway (mois) | B14: =IF(B13>0,B4/B13,99) -> 99 | C14: =IF(C13>0,C4/C13,99) -> 99 | D14: =IF(D13>0,D4/D13,99) -> 99
A15: Besoin financement | B15: =IF(B10<0,-B10,0) -> 0 | C15: =IF(C10<0,-C10,0) -> 0 | D15: =IF(D10<0,-D10,0) -> 0

Sheet KPIs
A1: KPIs — SERVICES / PRESTATIONS
A3: INDICATEUR | B3: Annee 1 | C3: Annee 2 | D3: Annee 3
A4: ACTIVITE
A5: CA total (euro) | B5: =Revenus!B15 -> 159200 | C5: =Revenus!C15 -> 378200 | D5: =Revenus!D15 -> 747600
A6: Missions realisees | B6: =Hypotheses!B13 -> 20 | C6: =Hypotheses!C13 -> 38 | D6: =Hypotheses!D13 -> 63
A7: Clients actifs | B7: =Hypotheses!B20 -> 10 | C7: =Hypotheses!C20 -> 29 | D7: =Hypotheses!D20 -> 58
A8: Taux recurrence | B8: =Hypotheses!B14 -> 0.25 | C8: =Hypotheses!C14 -> 0.35 | D8: =Hypotheses!D14 -> 0.45
A9: CA / consultant / an | B9: =Revenus!B18 -> 106133.33 | C9: =Revenus!C18 -> 126066.67 | D9: =Revenus!D18 -> 149520
A11: PRODUCTIVITE
A12: Consultants (ETP) | B12: =Hypotheses!B6 -> 1.5 | C12: =Hypotheses!C6 -> 3 | D12: =Hypotheses!D6 -> 5
A13: Taux d'occupation | B13: =Hypotheses!B8 -> 0.6 | C13: =Hypotheses!C8 -> 0.7 | D13: =Hypotheses!D8 -> 0.75
A14: TJM moyen (euro) | B14: =Hypotheses!B10 -> 800 | C14: =Hypotheses!C10 -> 850 | D14: =Hypotheses!D10 -> 900
A15: Jours factures / an | B15: =Hypotheses!B9 -> 196 | C15: =Hypotheses!C9 -> 458 | D15: =Hypotheses!D9 -> 818
A17: RENTABILITE
A18: Marge brute (%) | B18: ='Couts & P&L'!B21 -> 0.80987437 | C18: ='Couts & P&L'!C21 -> 0.81490481 | D18: ='Couts & P&L'!D21 -> 0.81814607
A19: EBITDA (euro) | B19: ='Couts & P&L'!B24 -> 80415.333 | C19: ='Couts & P&L'!C24 -> 109847 | D19: ='Couts & P&L'!D24 -> 316046
A20: Marge EBITDA | B20: ='Couts & P&L'!B25 -> 0.50512144 | C20: ='Couts & P&L'!C25 -> 0.29044685 | D20: ='Couts & P&L'!D25 -> 0.42274746
A21: Tresorerie (euro) | B21: =Tresorerie!B10 -> 99415.333 | C21: =Tresorerie!C10 -> 206262.33 | D21: =Tresorerie!D10 -> 517308.33
A22: CAC (euro) | B22: =Hypotheses!B19 -> 200 | C22: =Hypotheses!C19 -> 150 | D22: =Hypotheses!D19 -> 120

Sheet Mode d'emploi
A1: MODE D'EMPLOI — BP SERVICES / PRESTATIONS
A4: Ce template est adapte aux startups de services : conseil, agence, formation, prestations techniques...
A6: ETAPE 1 : Decrivez votre projet dans l'onglet Plan strategique
A7: ETAPE 2 : Remplissez l'onglet Hypotheses (cellules jaunes) :
A8: - CAPACITE : nombre de consultants, taux d'occupation, TJM
A9: - MISSIONS : panier moyen, duree, repartition forfait/regie
A10: - ACQUISITION : nouveaux clients/an, cout d'acquisition
A11: - COUTS : sous-traitance, deplacements, OPEX, equipe
A12: - FINANCEMENT : apports, subventions, levee
A13: ETAPE 3 : Verifiez les resultats dans Revenus, Couts, Tresorerie, KPIs
A15: CONVENTIONS : Jaune = a remplir | Gris italique = exemple | Vert = resultat cle | Orange = a surveiller | Rouge = alerte
A17: Astuce : demandez a Sam (Agent Finance FounderAI) de valider vos hypotheses de TJM et taux d'occupation !
