Workbook

Sheet Plan strategique
A1: BUSINESS PLAN SEED - DEEPTECH / INDUSTRIEL
A2: Template FounderAI - Cellules jaunes a remplir
A4: IDENTITE
A5: Nom | B5: CarbonLoop
A6: Secteur | B6: CleanTech - Captation CO2
A7: Date creation | B7: Sept 2025
A8: Fondateurs | B8: Dr. Rousseau (CEO), T. Vidal (CTO)
A9: Localisation | B9: Grenoble
A10: Stade | B10: TRL 4 - Prototype labo valide
A12: FEUILLE DE ROUTE TRL
A13: TRL 4 (actuel) | B13: Prototype labo valide | C13: 2025
A14: TRL 5-6 (Y1-Y2) | B14: Pilote echelle, validation terrain | C14: 2026-27
A15: TRL 7 (Y3) | B15: Demonstrateur pre-industriel | C15: 2028
A16: TRL 8-9 (Y4-Y5) | B16: Unite commerciale | C16: 2029-30
A18: MODELE ECONOMIQUE
A19: Revenu 1 | B19: Vente unites CAPEX 500K-2M euro/unite
A20: Revenu 2 | B20: Maintenance recurrente 15%/an
A21: Revenu 3 | B21: Credits carbone + subv exploitation

Sheet Hypotheses
A1: HYPOTHESES - DEEPTECH (5 ANS)
A3: REVENUS PRODUIT
B4: Y1 | C4: Y2 | D4: Y3 | E4: Y4 | F4: Y5 | G4: Y6 | H4: Y7
A5: Unites livrees | B5: 0 | C5: 0 | D5: 0 | E5: 2 | F5: 3 | G5: 5 | H5: 8
A6: Unites installees (cumul) | B6: 0 | C6: 0 | D6: 0 | E6: 2 | F6: 5 | G6: 8 | H6: 13
A7: Prix moyen / unite (euro) | B7: 0 | C7: 0 | D7: 0 | E7: 800000 | F7: 900000 | G7: 950000 | H7: 1000000
A8: CA Ventes unites | B8: =B5*B7 -> 0 | C8: =C5*C7 -> 0 | D8: =D5*D7 -> 0 | E8: =E5*E7 -> 1600000 | F8: =F5*F7 -> 2700000 | G8: =G5*G7 -> 4750000 | H8: =H5*H7 -> 8000000
A9: Taux maintenance (% CAPEX) | B9: 0 | C9: 0 | D9: 0 | E9: 0.15 | F9: 0.15 | G9: 0.15 | H9: 0.15
A10: CA Maintenance | B10: =B6*B7*B9 -> 0 | C10: =C6*C7*C9 -> 0 | D10: =D6*D7*D9 -> 0 | E10: =E6*E7*E9 -> 240000 | F10: =F6*F7*F9 -> 675000 | G10: =G6*G7*G9 -> 1140000 | H10: =H6*H7*H9 -> 1950000
A11: Revenus pilotes (euro) | B11: 0 | C11: 30000 | D11: 80000 | E11: 50000 | F11: 0 | G11: 0 | H11: 0
A12: Credits carbone (euro) | B12: 0 | C12: 0 | D12: 0 | E12: 20000 | F12: 60000 | G12: 100000 | H12: 150000
A13: CA TOTAL | B13: =B8+B10+B11+B12 -> 0 | C13: =C8+C10+C11+C12 -> 30000 | D13: =D8+D10+D11+D12 -> 80000 | E13: =E8+E10+E11+E12 -> 1910000 | F13: =F8+F10+F11+F12 -> 3435000 | G13: =G8+G10+G11+G12 -> 5990000 | H13: =H8+H10+H11+H12 -> 10100000
A15: DEPENSES R&D
B16: Y1 | C16: Y2 | D16: Y3 | E16: Y4 | F16: Y5 | G16: Y6 | H16: Y7
A17: Personnel R&D (brut charge) | B17: 180000 | C17: 320000 | D17: 400000 | E17: 350000 | F17: 300000 | G17: 200000 | H17: 150000
A18: Materiaux & consommables | B18: 40000 | C18: 60000 | D18: 80000 | E18: 50000 | F18: 30000 | G18: 20000 | H18: 15000
A19: Equipements | B19: 30000 | C19: 50000 | D19: 100000 | E19: 40000 | F19: 20000 | G19: 10000 | H19: 5000
A20: Sous-traitance R&D | B20: 20000 | C20: 40000 | D20: 60000 | E20: 30000 | F20: 15000 | G20: 10000 | H20: 5000
A21: Propriete intellectuelle | B21: 15000 | C21: 20000 | D21: 15000 | E21: 10000 | F21: 10000 | G21: 10000 | H21: 10000
A22: Deplacements R&D | B22: 5000 | C22: 10000 | D22: 15000 | E22: 10000 | F22: 8000 | G22: 5000 | H22: 3000
A23: Total depenses R&D | B23: =SUM(B17:B22) -> 290000 | C23: =SUM(C17:C22) -> 500000 | D23: =SUM(D17:D22) -> 670000 | E23: =SUM(E17:E22) -> 490000 | F23: =SUM(F17:F22) -> 383000 | G23: =SUM(G17:G22) -> 255000 | H23: =SUM(H17:H22) -> 188000
A25: FINANCEMENT R&D (NON-DILUTIF)
B26: Y1 | C26: Y2 | D26: Y3 | E26: Y4 | F26: Y5 | G26: Y6 | H26: Y7
A27: CIR (30% auto) | B27: =ROUND(B23*0.3,0) -> 87000 | C27: =ROUND(C23*0.3,0) -> 150000 | D27: =ROUND(D23*0.3,0) -> 201000 | E27: =ROUND(E23*0.3,0) -> 147000 | F27: =ROUND(F23*0.3,0) -> 114900 | G27: =ROUND(G23*0.3,0) -> 76500 | H27: =ROUND(H23*0.3,0) -> 56400
A28: CII | B28: 0 | C28: 0 | D28: 10000 | E28: 15000 | F28: 20000 | G28: 15000 | H28: 10000
A29: Subvention BPI | B29: 0 | C29: 100000 | D29: 80000 | E29: 0 | F29: 0 | G29: 0 | H29: 0
A30: ADEME / Region | B30: 50000 | C30: 0 | D30: 60000 | E30: 0 | F30: 0 | G30: 0 | H30: 0
A31: Subvention EU (EIC, HE) | B31: 0 | C31: 0 | D31: 200000 | E31: 0 | F31: 0 | G31: 0 | H31: 0
A32: Concours innovation | B32: 30000 | C32: 20000 | D32: 0 | E32: 0 | F32: 0 | G32: 0 | H32: 0
A33: Total non-dilutif | B33: =SUM(B27:B32) -> 167000 | C33: =SUM(C27:C32) -> 270000 | D33: =SUM(D27:D32) -> 551000 | E33: =SUM(E27:E32) -> 162000 | F33: =SUM(F27:F32) -> 134900 | G33: =SUM(G27:G32) -> 91500 | H33: =SUM(H27:H32) -> 66400
A34: Cout R&D net | B34: =B23-B33 -> 123000 | C34: =C23-C33 -> 230000 | D34: =D23-D33 -> 119000 | E34: =E23-E33 -> 328000 | F34: =F23-F33 -> 248100 | G34: =G23-G33 -> 163500 | H34: =H23-H33 -> 121600
A36: COUTS FIXES (HORS R&D)
A37: Poste | B37: Y1/mois | C37: Y2/mois | D37: Y3/mois | E37: Y4/mois | F37: Y5/mois | G37: Y6 | H37: Y7
A38: Loyer labo | B38: 800 | C38: 1200 | D38: 2000 | E38: 3000 | F38: 4000 | G38: 5000 | H38: 6000
A39: Outils & abonnements | B39: 200 | C39: 300 | D39: 500 | E39: 700 | F39: 900 | G39: 1100 | H39: 1300
A40: Comptabilite / juridique | B40: 300 | C40: 500 | D40: 700 | E40: 900 | F40: 1200 | G40: 1500 | H40: 1800
A41: Marketing / BD | B41: 200 | C41: 500 | D41: 1500 | E41: 3000 | F41: 5000 | G41: 7000 | H41: 9000
A42: Assurances | B42: 150 | C42: 200 | D42: 400 | E42: 600 | F42: 800 | G42: 1000 | H42: 1200
A43: Divers | B43: 150 | C43: 300 | D43: 400 | E43: 500 | F43: 600 | G43: 700 | H43: 800
A44: Total OPEX / an | B44: =SUM(B38:B43)*12 -> 21600 | C44: =SUM(C38:C43)*12 -> 36000 | D44: =SUM(D38:D43)*12 -> 66000 | E44: =SUM(E38:E43)*12 -> 104400 | F44: =SUM(F38:F43)*12 -> 150000 | G44: =SUM(G38:G43)*12 -> 195600 | H44: =SUM(H38:H43)*12 -> 241200
...

Sheet Revenus
A1: REVENUS - DEEPTECH
B3: Y1 | C3: Y2 | D3: Y3 | E3: Y4 | F3: Y5 | G3: Y6 | H3: Y7
A4: CA Ventes unites | B4: =Hypotheses!B8 -> 0 | C4: =Hypotheses!C8 -> 0 | D4: =Hypotheses!D8 -> 0 | E4: =Hypotheses!E8 -> 1600000 | F4: =Hypotheses!F8 -> 2700000 | G4: =Hypotheses!G8 -> 4750000 | H4: =Hypotheses!H8 -> 8000000
A5: CA Maintenance | B5: =Hypotheses!B10 -> 0 | C5: =Hypotheses!C10 -> 0 | D5: =Hypotheses!D10 -> 0 | E5: =Hypotheses!E10 -> 240000 | F5: =Hypotheses!F10 -> 675000 | G5: =Hypotheses!G10 -> 1140000 | H5: =Hypotheses!H10 -> 1950000
A6: Revenus pilotes | B6: =Hypotheses!B11 -> 0 | C6: =Hypotheses!C11 -> 30000 | D6: =Hypotheses!D11 -> 80000 | E6: =Hypotheses!E11 -> 50000 | F6: =Hypotheses!F11 -> 0 | G6: =Hypotheses!G11 -> 0 | H6: =Hypotheses!H11 -> 0
A7: Credits carbone | B7: =Hypotheses!B12 -> 0 | C7: =Hypotheses!C12 -> 0 | D7: =Hypotheses!D12 -> 0 | E7: =Hypotheses!E12 -> 20000 | F7: =Hypotheses!F12 -> 60000 | G7: =Hypotheses!G12 -> 100000 | H7: =Hypotheses!H12 -> 150000
A8: CA TOTAL | B8: =Hypotheses!B13 -> 0 | C8: =Hypotheses!C13 -> 30000 | D8: =Hypotheses!D13 -> 80000 | E8: =Hypotheses!E13 -> 1910000 | F8: =Hypotheses!F13 -> 3435000 | G8: =Hypotheses!G13 -> 5990000 | H8: =Hypotheses!H13 -> 10100000
A10: Financement non-dilutif R&D | B10: =Hypotheses!B33 -> 167000 | C10: =Hypotheses!C33 -> 270000 | D10: =Hypotheses!D33 -> 551000 | E10: =Hypotheses!E33 -> 162000 | F10: =Hypotheses!F33 -> 134900 | G10: =Hypotheses!G33 -> 91500 | H10: =Hypotheses!H33 -> 66400
A11: Total ressources | B11: =B8+B10 -> 167000 | C11: =C8+C10 -> 300000 | D11: =D8+D10 -> 631000 | E11: =E8+E10 -> 2072000 | F11: =F8+F10 -> 3569900 | G11: =G8+G10 -> 6081500 | H11: =H8+H10 -> 10166400

Sheet Couts & PL
A1: COUTS & COMPTE DE RESULTAT
B3: Y1 | C3: Y2 | D3: Y3 | E3: Y4 | F3: Y5 | G3: Y6 | H3: Y7
A4: CA Total | B4: =Revenus!B8 -> 0 | C4: =Revenus!C8 -> 30000 | D4: =Revenus!D8 -> 80000 | E4: =Revenus!E8 -> 1910000 | F4: =Revenus!F8 -> 3435000 | G4: =Revenus!G8 -> 5990000 | H4: =Revenus!H8 -> 10100000
A5: COGS (production unites) | B5: 0 | C5: 0 | D5: 0 | E5: 500000 | F5: 900000 | G5: 1500000 | H5: 2400000
A6: Marge brute | B6: =B4-B5 -> 0 | C6: =C4-C5 -> 30000 | D6: =D4-D5 -> 80000 | E6: =E4-E5 -> 1410000 | F6: =F4-F5 -> 2535000 | G6: =G4-G5 -> 4490000 | H6: =H4-H5 -> 7700000
A8: Depenses R&D | B8: =-Hypotheses!B23 -> -290000 | C8: =-Hypotheses!C23 -> -500000 | D8: =-Hypotheses!D23 -> -670000 | E8: =-Hypotheses!E23 -> -490000 | F8: =-Hypotheses!F23 -> -383000 | G8: =-Hypotheses!G23 -> -255000 | H8: =-Hypotheses!H23 -> -188000
A9: OPEX hors R&D | B9: =-Hypotheses!B44 -> -21600 | C9: =-Hypotheses!C44 -> -36000 | D9: =-Hypotheses!D44 -> -66000 | E9: =-Hypotheses!E44 -> -104400 | F9: =-Hypotheses!F44 -> -150000 | G9: =-Hypotheses!G44 -> -195600 | H9: =-Hypotheses!H44 -> -241200
A10: Masse salariale hors R&D | B10: =-ABS(Hypotheses!B57) -> 0 | C10: =-ABS(Hypotheses!C57) -> -126391.67 | D10: =-ABS(Hypotheses!D57) -> -200583.33 | E10: =-ABS(Hypotheses!E57) -> -217500 | F10: =-ABS(Hypotheses!F57) -> -217500 | G10: =-ABS(Hypotheses!G57) -> -217500 | H10: =-ABS(Hypotheses!H57) -> -217500
A12: EBITDA (avant aides) | B12: =B6+B8+B9+B10 -> -311600 | C12: =C6+C8+C9+C10 -> -632391.67 | D12: =D6+D8+D9+D10 -> -856583.33 | E12: =E6+E8+E9+E10 -> 598100 | F12: =F6+F8+F9+F10 -> 1784500 | G12: =G6+G8+G9+G10 -> 3821900 | H12: =H6+H8+H9+H10 -> 7053300
A13: Financement non-dilutif | B13: =Hypotheses!B33 -> 167000 | C13: =Hypotheses!C33 -> 270000 | D13: =Hypotheses!D33 -> 551000 | E13: =Hypotheses!E33 -> 162000 | F13: =Hypotheses!F33 -> 134900 | G13: =Hypotheses!G33 -> 91500 | H13: =Hypotheses!H33 -> 66400
A14: Resultat net (apres aides) | B14: =B12+B13 -> -144600 | C14: =C12+C13 -> -362391.67 | D14: =D12+D13 -> -305583.33 | E14: =E12+E13 -> 760100 | F14: =F12+F13 -> 1919400 | G14: =G12+G13 -> 3913400 | H14: =H12+H13 -> 7119700

Sheet Tresorerie
A1: TRESORERIE
B3: Y1 | C3: Y2 | D3: Y3 | E3: Y4 | F3: Y5 | G3: Y6 | H3: Y7
A4: Tresorerie debut | B4: =Hypotheses!B65 -> 880000 | C4: =B12 -> 1610400 | D4: =C12 -> 1233008.3 | E4: =D12 -> 897425 | F4: =E12 -> 1637525 | G4: =F12 -> 3546925 | H4: =G12 -> 7455325
A5: CA | B5: =Revenus!B8 -> 0 | C5: =Revenus!C8 -> 30000 | D5: =Revenus!D8 -> 80000 | E5: =Revenus!E8 -> 1910000 | F5: =Revenus!F8 -> 3435000 | G5: =Revenus!G8 -> 5990000 | H5: =Revenus!H8 -> 10100000
A6: Aides non-dilutif | B6: =Hypotheses!B33 -> 167000 | C6: =Hypotheses!C33 -> 270000 | D6: =Hypotheses!D33 -> 551000 | E6: =Hypotheses!E33 -> 162000 | F6: =Hypotheses!F33 -> 134900 | G6: =Hypotheses!G33 -> 91500 | H6: =Hypotheses!H33 -> 66400
A7: Decaissements | B7: ='Couts & PL'!B12-'Couts & PL'!B4 -> -311600 | C7: ='Couts & PL'!C12-'Couts & PL'!C4 -> -662391.67 | D7: ='Couts & PL'!D12-'Couts & PL'!D4 -> -936583.33 | E7: ='Couts & PL'!E12-'Couts & PL'!E4 -> -1311900 | F7: ='Couts & PL'!F12-'Couts & PL'!F4 -> -1650500 | G7: ='Couts & PL'!G12-'Couts & PL'!G4 -> -2168100 | H7: ='Couts & PL'!H12-'Couts & PL'!H4 -> -3046700
A8: CAPEX hors R&D | B8: -5000 | C8: -15000 | D8: -30000 | E8: -20000 | F8: -10000 | G8: -5000 | H8: -5000
A9: Financement dilutif | B9: 880000 | C9: 0 | D9: 0 | E9: 0 | F9: 0 | G9: 0 | H9: 0
A10: Remboursements | B10: 0 | C10: 0 | D10: 0 | E10: 0 | F10: 0 | G10: 0 | H10: 0
A11: Flux net | B11: =SUM(B5:B10) -> 730400 | C11: =SUM(C5:C10) -> -377391.67 | D11: =SUM(D5:D10) -> -335583.33 | E11: =SUM(E5:E10) -> 740100 | F11: =SUM(F5:F10) -> 1909400 | G11: =SUM(G5:G10) -> 3908400 | H11: =SUM(H5:H10) -> 7114700
A12: Tresorerie fin | B12: =B4+B11 -> 1610400 | C12: =C4+C11 -> 1233008.3 | D12: =D4+D11 -> 897425 | E12: =E4+E11 -> 1637525 | F12: =F4+F11 -> 3546925 | G12: =G4+G11 -> 7455325 | H12: =H4+H11 -> 14570025
A14: Burn rate mensuel | B14: =IF(B11<0,-B11/12,0) -> 0 | C14: =IF(C11<0,-C11/12,0) -> 31449.306 | D14: =IF(D11<0,-D11/12,0) -> 27965.278 | E14: =IF(E11<0,-E11/12,0) -> 0 | F14: =IF(F11<0,-F11/12,0) -> 0 | G14: =IF(G11<0,-G11/12,0) -> 0 | H14: =IF(H11<0,-H11/12,0) -> 0
A15: Runway (mois) | B15: =IF(B14>0,B4/B14,99) -> 99 | C15: =IF(C14>0,C4/C14,99) -> 51.206218 | D15: =IF(D14>0,D4/D14,99) -> 44.090688 | E15: =IF(E14>0,E4/E14,99) -> 99 | F15: =IF(F14>0,F4/F14,99) -> 99 | G15: =IF(G14>0,G4/G14,99) -> 99 | H15: =IF(H14>0,H4/H14,99) -> 99

Sheet KPIs
A1: KPIs - DEEPTECH
A3: INDICATEUR | B3: Y1 | C3: Y2 | D3: Y3 | E3: Y4 | F3: Y5 | G3: Y6 | H3: Y7
A4: R&D
A5: Depenses R&D | B5: =Hypotheses!B23 -> 290000 | C5: =Hypotheses!C23 -> 500000 | D5: =Hypotheses!D23 -> 670000 | E5: =Hypotheses!E23 -> 490000 | F5: =Hypotheses!F23 -> 383000 | G5: =Hypotheses!G23 -> 255000 | H5: =Hypotheses!H23 -> 188000
A6: Financement non-dilutif | B6: =Hypotheses!B33 -> 167000 | C6: =Hypotheses!C33 -> 270000 | D6: =Hypotheses!D33 -> 551000 | E6: =Hypotheses!E33 -> 162000 | F6: =Hypotheses!F33 -> 134900 | G6: =Hypotheses!G33 -> 91500 | H6: =Hypotheses!H33 -> 66400
A7: Cout R&D net | B7: =Hypotheses!B34 -> 123000 | C7: =Hypotheses!C34 -> 230000 | D7: =Hypotheses!D34 -> 119000 | E7: =Hypotheses!E34 -> 328000 | F7: =Hypotheses!F34 -> 248100 | G7: =Hypotheses!G34 -> 163500 | H7: =Hypotheses!H34 -> 121600
A8: % R&D financee | B8: =IF(Hypotheses!B23>0,Hypotheses!B33/Hypotheses!B23,0) -> 0.57586207 | C8: =IF(Hypotheses!C23>0,Hypotheses!C33/Hypotheses!C23,0) -> 0.54 | D8: =IF(Hypotheses!D23>0,Hypotheses!D33/Hypotheses!D23,0) -> 0.82238806 | E8: =IF(Hypotheses!E23>0,Hypotheses!E33/Hypotheses!E23,0) -> 0.33061224 | F8: =IF(Hypotheses!F23>0,Hypotheses!F33/Hypotheses!F23,0) -> 0.35221932 | G8: =IF(Hypotheses!G23>0,Hypotheses!G33/Hypotheses!G23,0) -> 0.35882353 | H8: =IF(Hypotheses!H23>0,Hypotheses!H33/Hypotheses!H23,0) -> 0.35319149
A10: REVENUS
A11: CA total | B11: =Revenus!B8 -> 0 | C11: =Revenus!C8 -> 30000 | D11: =Revenus!D8 -> 80000 | E11: =Revenus!E8 -> 1910000 | F11: =Revenus!F8 -> 3435000 | G11: =Revenus!G8 -> 5990000 | H11: =Revenus!H8 -> 10100000
A12: Unites installees | B12: =Hypotheses!B6 -> 0 | C12: =Hypotheses!C6 -> 0 | D12: =Hypotheses!D6 -> 0 | E12: =Hypotheses!E6 -> 2 | F12: =Hypotheses!F6 -> 5 | G12: =Hypotheses!G6 -> 8 | H12: =Hypotheses!H6 -> 13
A13: CA maintenance | B13: =Revenus!B5 -> 0 | C13: =Revenus!C5 -> 0 | D13: =Revenus!D5 -> 0 | E13: =Revenus!E5 -> 240000 | F13: =Revenus!F5 -> 675000 | G13: =Revenus!G5 -> 1140000 | H13: =Revenus!H5 -> 1950000
A15: RENTABILITE
A16: EBITDA avant aides | B16: ='Couts & PL'!B12 -> -311600 | C16: ='Couts & PL'!C12 -> -632391.67 | D16: ='Couts & PL'!D12 -> -856583.33 | E16: ='Couts & PL'!E12 -> 598100 | F16: ='Couts & PL'!F12 -> 1784500 | G16: ='Couts & PL'!G12 -> 3821900 | H16: ='Couts & PL'!H12 -> 7053300
A17: Resultat apres aides | B17: ='Couts & PL'!B14 -> -144600 | C17: ='Couts & PL'!C14 -> -362391.67 | D17: ='Couts & PL'!D14 -> -305583.33 | E17: ='Couts & PL'!E14 -> 760100 | F17: ='Couts & PL'!F14 -> 1919400 | G17: ='Couts & PL'!G14 -> 3913400 | H17: ='Couts & PL'!H14 -> 7119700
A18: Tresorerie | B18: =Tresorerie!B12 -> 1610400 | C18: =Tresorerie!C12 -> 1233008.3 | D18: =Tresorerie!D12 -> 897425 | E18: =Tresorerie!E12 -> 1637525 | F18: =Tresorerie!F12 -> 3546925 | G18: =Tresorerie!G12 -> 7455325 | H18: =Tresorerie!H12 -> 14570025
A19: Runway (mois) | B19: =Tresorerie!B15 -> 99 | C19: =Tresorerie!C15 -> 51.206218 | D19: =Tresorerie!D15 -> 44.090688 | E19: =Tresorerie!E15 -> 99 | F19: =Tresorerie!F15 -> 99 | G19: =Tresorerie!G15 -> 99 | H19: =Tresorerie!H15 -> 99

Sheet Mode d'emploi
A1: MODE D'EMPLOI - BP DEEPTECH
A4: Template pour startups DeepTech, industrielles, CleanTech, hardware, materiaux.
A5: Horizon 5 ans - R&D detaillee - CIR automatique - Financement non-dilutif
A7: ETAPE 1 : Plan strategique (TRL, brevets, feuille de route)
A8: ETAPE 2 : Hypotheses (revenus, R&D, financement, equipe)
A9: ETAPE 3 : Verifier Revenus, Couts, Tresorerie, KPIs
A11: CLE : CIR calcule auto a 30% des depenses R&D.
A12: Surveillez le runway et planifiez les levees 6-9 mois a l avance.
A14: Demandez a Sam (Agent Finance FounderAI) de valider vos hypotheses !
