Workbook

Sheet Plan stratégique
A1: BUSINESS PLAN SEED — MODÈLE MARKETPLACE
A2: Template FounderAI • Cellules jaunes à remplir (exemples gris à écraser)
A4: IDENTITÉ DU PROJET
A5: Nom de la startup | B5: TalentFlash
A6: Secteur | B6: Marketplace freelances tech
A7: Date de création | B7: Mars 2026
A8: Fondateur(s) | B8: Lucas Morel (CEO), Inès Farah (CPO)
A9: Localisation | B9: Lyon, France
A10: Stade actuel | B10: Beta avec 50 freelances inscrits
A12: PROBLÈME & SOLUTION
A13: Problème résolu | B13: Les PME mettent 3 semaines et 2 000€ pour trouver un freelance tech qualifié
A14: Solution proposée | B14: Marketplace de mise en relation instantanée entre PME et freelances tech vérifiés, matching IA en 48h
A15: Proposition de valeur unique | B15: Freelances pré-qualifiés par IA + garantie satisfaction ou remplacement gratuit
A17: MARCHÉ & MODÈLE
A18: TAM | B18: 15 Mds€ — Marché européen du freelancing tech
A19: SAM | B19: 1,2 Md€ — PME françaises qui recrutent des freelances tech
A20: SOM (3 ans) | B20: 3 M€ GMV — 1 500 missions à 2 000€ de panier moyen
A21: Type de marketplace | B21: Services (freelance → client), commission sur transaction | C21: Biens / Services / Hybride
A22: Client idéal — Demande | B22: CTO ou DRH de PME tech, 20-200 salariés, besoin urgent de devs | C22: Qui achète ?
A23: Client idéal — Offre | B23: Développeur freelance senior, 5+ ans, full-stack ou data | C23: Qui vend ?
A25: MILESTONES 18 MOIS
A26: M1-M3 | B26: 100 freelances inscrits, 10 PME clientes, 15 missions réalisées
A27: M4-M6 | B27: 300 freelances, 40 PME, 80 missions, 160K€ GMV
A28: M7-M12 | B28: 800 freelances, 120 PME, 400 missions, 800K€ GMV
A29: M13-M18 | B29: 1 500 freelances, 300 PME, 1 000 missions, 2M€ GMV

Sheet Hypothèses
A1: HYPOTHÈSES — MODÈLE MARKETPLACE
A2: Cellules jaunes = vos hypothèses. Le reste se calcule automatiquement.
A4: VOLUMÉTRIE & TRANSACTION
B5: Année 1 | C5: Année 2 | D5: Année 3 | E5: Notes
A6: Transactions / mois (moy.) | B6: 20 | C6: 80 | D6: 200 | E6: Missions réalisées
A7: Panier moyen par transaction (€) | B7: 2000 | C7: 2200 | D7: 2500 | E7: Valeur moyenne d'une mission
A8: Taux de commission (take rate) | B8: 0.12 | C8: 0.12 | D8: 0.15 | E8: Commission prélevée
A9: GMV mensuelle (calculé) | B9: =B6*B7 -> 40000 | C9: =C6*C7 -> 176000 | D9: =D6*D7 -> 500000 | E9: transactions × panier
A10: CA mensuel commission (calculé) | B10: =B9*B8 -> 4800 | C10: =C9*C8 -> 21120 | D10: =D9*D8 -> 75000 | E10: gmv × take rate
A12: OFFRE & DEMANDE
B13: Année 1 | C13: Année 2 | D13: Année 3 | E13: Notes
A14: Offreurs inscrits (fin d'année) | B14: 200 | C14: 800 | D14: 1500 | E14: Freelances / vendeurs
A15: Offreurs actifs (%) | B15: 0.3 | C15: 0.35 | D15: 0.4 | E15: % qui réalisent ≥1 mission
A16: Demandeurs actifs (fin d'année) | B16: 50 | C16: 150 | D16: 400 | E16: PME / acheteurs actifs
A17: Transactions / offreur actif / an | B17: =IF(B14*B15>0,B6*12/(B14*B15),0) -> 4 | C17: =IF(C14*C15>0,C6*12/(C14*C15),0) -> 3.4285714 | D17: =IF(D14*D15>0,D6*12/(D14*D15),0) -> 4 | E17: Calculé
A18: Transactions / demandeur / an | B18: =IF(B16>0,B6*12/B16,0) -> 4.8 | C18: =IF(C16>0,C6*12/C16,0) -> 6.4 | D18: =IF(D16>0,D6*12/D16,0) -> 6 | E18: Calculé
A19: Taux de réachat demandeurs | B19: 0.4 | C19: 0.55 | D19: 0.65 | E19: % qui reviennent
A21: COÛTS D'ACQUISITION
B22: Année 1 | C22: Année 2 | D22: Année 3 | E22: Notes
A23: CAC offreur (€) | B23: 20 | C23: 15 | D23: 10 | E23: Coût pour recruter 1 freelance
A24: CAC demandeur (€) | B24: 80 | C24: 60 | D24: 45 | E24: Coût pour acquérir 1 client PME
A25: Budget acquisition offreurs / an | B25: =B14*B23 -> 4000 | C25: =C14*C23 -> 12000 | D25: =D14*D23 -> 15000 | E25: Calculé
A26: Budget acquisition demandeurs / an | B26: =B16*B24 -> 4000 | C26: =C16*C24 -> 9000 | D26: =D16*D24 -> 18000 | E26: Calculé
A28: COÛTS VARIABLES UNITAIRES
B29: % du GMV ou €/tx | E29: Notes
A30: Frais de paiement (% GMV) | B30: 0.029 | E30: Stripe/Mangopay
A31: Assurance / garantie (% GMV) | B31: 0.01 | E31: Garantie satisfaction
A32: Coût matching / vérification (€/tx) | B32: 5 | E32: Vérification profils, IA
A34: COÛTS FIXES MENSUELS
A35: Poste | B35: Année 1 /mois | C35: Année 2 /mois | D35: Année 3 /mois | E35: Notes
A36: Hébergement / infra | B36: 200 | C36: 500 | D36: 1200 | E36: Serveurs, CDN, API
A37: Abonnements outils | B37: 150 | C37: 350 | D37: 600 | E37: CRM, analytics, support
A38: Comptabilité / juridique | B38: 200 | C38: 400 | D38: 600 | E38: Expert-comptable
A39: Marketing & contenu | B39: 500 | C39: 2000 | D39: 4000 | E39: SEO, ads, events
A40: Assurances | B40: 50 | C40: 100 | D40: 200
A41: Divers | B41: 100 | C41: 300 | D41: 500
A42: Total OPEX / an | B42: =SUM(B36:B41)*12 -> 14400 | C42: =SUM(C36:C41)*12 -> 43800 | D42: =SUM(D36:D41)*12 -> 85200
A44: ÉQUIPE
A45: Poste | B45: Mois entrée | C45: Brut/an (€) | E45: Notes
A46: Fondateur 1 | B46: 1 | C46: 0
...

Sheet Revenus
A1: PROJECTIONS DE REVENUS — MARKETPLACE
A2: Calculé depuis l'onglet Hypothèses
B4: Année 1 | C4: Année 2 | D4: Année 3
A5: Transactions totales | B5: =B6*12 -> 240 | C5: =C6*12 -> 960 | D5: =D6*12 -> 2400
A6: Transactions / mois | B6: =Hypothèses!B6 -> 20 | C6: =Hypothèses!C6 -> 80 | D6: =Hypothèses!D6 -> 200 | E6: Depuis Hypothèses
A7: Panier moyen (€) | B7: =Hypothèses!B7 -> 2000 | C7: =Hypothèses!C7 -> 2200 | D7: =Hypothèses!D7 -> 2500
A8: GMV annuelle (€) | B8: =B5*B7 -> 480000 | C8: =C5*C7 -> 2112000 | D8: =D5*D7 -> 6000000 | E8: Volume total de transactions
A9: Take rate | B9: =Hypothèses!B8 -> 0.12 | C9: =Hypothèses!C8 -> 0.12 | D9: =Hypothèses!D8 -> 0.15
A10: CA Commissions (€) | B10: =B8*B9 -> 57600 | C10: =C8*C9 -> 253440 | D10: =D8*D9 -> 900000 | E10: Revenu net marketplace
A12: Revenus additionnels
A13: Abonnements premium offreurs | B13: 0 | C13: 0 | D13: 0 | E13: Optionnel — visibilité boost
A14: Services à valeur ajoutée | B14: 0 | C14: 0 | D14: 0 | E14: Assurance, formation, admin
A15: CA TOTAL | B15: =B10+B13+B14 -> 57600 | C15: =C10+C13+C14 -> 253440 | D15: =D10+D13+D14 -> 900000

Sheet Coûts & P&L
A1: COÛTS & COMPTE DE RÉSULTAT
B3: Année 1 | C3: Année 2 | D3: Année 3 | E3: Notes
A4: COÛTS VARIABLES
A5: Frais de paiement | B5: =-Revenus!B8*Hypothèses!B30 -> -13920 | C5: =-Revenus!C8*Hypothèses!B30 -> -61248 | D5: =-Revenus!D8*Hypothèses!B30 -> -174000
A6: Assurance / garantie | B6: =-Revenus!B8*Hypothèses!B31 -> -4800 | C6: =-Revenus!C8*Hypothèses!B31 -> -21120 | D6: =-Revenus!D8*Hypothèses!B31 -> -60000
A7: Coûts matching / vérification | B7: =-Hypothèses!B32*Revenus!B5 -> -1200 | C7: =-Hypothèses!B32*Revenus!C5 -> -4800 | D7: =-Hypothèses!B32*Revenus!D5 -> -12000
A8: Acquisition offreurs | B8: =-Hypothèses!B25 -> -4000 | C8: =-Hypothèses!C25 -> -12000 | D8: =-Hypothèses!D25 -> -15000
A9: Acquisition demandeurs | B9: =-Hypothèses!B26 -> -4000 | C9: =-Hypothèses!C26 -> -9000 | D9: =-Hypothèses!D26 -> -18000
A10: Total coûts variables | B10: =SUM(B5:B9) -> -27920 | C10: =SUM(C5:C9) -> -108168 | D10: =SUM(D5:D9) -> -279000
A12: COÛTS FIXES & SALAIRES
A13: OPEX annuel | B13: =-Hypothèses!B42 -> -14400 | C13: =-Hypothèses!C42 -> -43800 | D13: =-Hypothèses!D42 -> -85200
A14: Masse salariale chargée | B14: =-ABS(Hypothèses!B55) -> -26583.333 | C14: =-ABS(Hypothèses!C55) -> -181491.67 | D14: =-ABS(Hypothèses!D55) -> -189950
A15: Total coûts fixes + salaires | B15: =B13+B14 -> -40983.333 | C15: =C13+C14 -> -225291.67 | D15: =D13+D14 -> -275150
A17: COMPTE DE RÉSULTAT
B18: Année 1 | C18: Année 2 | D18: Année 3
A19: Chiffre d'affaires | B19: =Revenus!B15 -> 57600 | C19: =Revenus!C15 -> 253440 | D19: =Revenus!D15 -> 900000
A20: Coûts variables | B20: =B10 -> -27920 | C20: =C10 -> -108168 | D20: =D10 -> -279000
A21: Marge brute | B21: =B19+B20 -> 29680 | C21: =C19+C20 -> 145272 | D21: =D19+D20 -> 621000
A22: % Marge brute | B22: =IF(B19=0,0,B21/B19) -> 0.51527778 | C22: =IF(C19=0,0,C21/C19) -> 0.57320076 | D22: =IF(D19=0,0,D21/D19) -> 0.69
A23: Coûts fixes + salaires | B23: =B15 -> -40983.333 | C23: =C15 -> -225291.67 | D23: =D15 -> -275150
A25: EBITDA | B25: =B21+B23 -> -11303.333 | C25: =C21+C23 -> -80019.667 | D25: =D21+D23 -> 345850
A26: % Marge EBITDA | B26: =IF(B19=0,0,B25/B19) -> -0.19623843 | C26: =IF(C19=0,0,C25/C19) -> -0.31573416 | D26: =IF(D19=0,0,D25/D19) -> 0.38427778

Sheet Trésorerie
A1: PLAN DE TRÉSORERIE
B3: Année 1 | C3: Année 2 | D3: Année 3
A4: Trésorerie début | B4: =Hypothèses!B62 -> 20000 | C4: =B10 -> 25696.667 | D4: =C10 -> -62323
A5: Encaissements | B5: =Revenus!B15 -> 57600 | C5: =Revenus!C15 -> 253440 | D5: =Revenus!D15 -> 900000
A6: Décaissements | B6: ='Coûts & P&L'!B25-'Coûts & P&L'!B19 -> -68903.333 | C6: ='Coûts & P&L'!C25-'Coûts & P&L'!C19 -> -333459.67 | D6: ='Coûts & P&L'!D25-'Coûts & P&L'!D19 -> -554150
A7: CAPEX | B7: -3000 | C7: -8000 | D7: -15000
A8: Apports financement | B8: =Hypothèses!B62 -> 20000 | C8: 0 | D8: 0
A9: Flux net | B9: =B5+B6+B7+B8 -> 5696.6667 | C9: =C5+C6+C7+C8 -> -88019.667 | D9: =D5+D6+D7+D8 -> 330850
A10: Trésorerie fin | B10: =B4+B9 -> 25696.667 | C10: =C4+C9 -> -62323 | D10: =D4+D9 -> 268527
A12: MÉTRIQUES
A13: Burn rate mensuel | B13: =IF(B9<0,-B9/12,0) -> 0 | C13: =IF(C9<0,-C9/12,0) -> 7334.9722 | D13: =IF(D9<0,-D9/12,0) -> 0
A14: Runway (mois) | B14: =IF(B13>0,B4/B13,99) -> 99 | C14: =IF(C13>0,C4/C13,99) -> 3.503308 | D14: =IF(D13>0,D4/D13,99) -> 99
A15: Besoin financement | B15: =IF(B10<0,-B10,0) -> 0 | C15: =IF(C10<0,-C10,0) -> 62323 | D15: =IF(D10<0,-D10,0) -> 0

Sheet KPIs
A1: KPIs — MARKETPLACE
A3: INDICATEUR | B3: Année 1 | C3: Année 2 | D3: Année 3
A4: VOLUME & CROISSANCE
A5: GMV annuelle (€) | B5: =Revenus!B8 -> 480000 | C5: =Revenus!C8 -> 2112000 | D5: =Revenus!D8 -> 6000000
A6: Transactions totales | B6: =Revenus!B5 -> 240 | C6: =Revenus!C5 -> 960 | D6: =Revenus!D5 -> 2400
A7: Panier moyen (€) | B7: =Revenus!B7 -> 2000 | C7: =Revenus!C7 -> 2200 | D7: =Revenus!D7 -> 2500
A8: CA total (€) | B8: =Revenus!B15 -> 57600 | C8: =Revenus!C15 -> 253440 | D8: =Revenus!D15 -> 900000
A9: Take rate effectif | B9: =IF(Revenus!B8>0,Revenus!B10/Revenus!B8,0) -> 0.12 | C9: =IF(Revenus!C8>0,Revenus!C10/Revenus!C8,0) -> 0.12 | D9: =IF(Revenus!D8>0,Revenus!D10/Revenus!D8,0) -> 0.15
A11: LIQUIDITÉ MARKETPLACE
A12: Offreurs inscrits | B12: =Hypothèses!B14 -> 200 | C12: =Hypothèses!C14 -> 800 | D12: =Hypothèses!D14 -> 1500
A13: Offreurs actifs (%) | B13: =Hypothèses!B15 -> 0.3 | C13: =Hypothèses!C15 -> 0.35 | D13: =Hypothèses!D15 -> 0.4
A14: Demandeurs actifs | B14: =Hypothèses!B16 -> 50 | C14: =Hypothèses!C16 -> 150 | D14: =Hypothèses!D16 -> 400
A15: Tx réachat demandeurs | B15: =Hypothèses!B19 -> 0.4 | C15: =Hypothèses!C19 -> 0.55 | D15: =Hypothèses!D19 -> 0.65
A16: Ratio offre/demande | B16: =IF(Hypothèses!B16>0,Hypothèses!B14*Hypothèses!B15/Hypothèses!B16,0) -> 1.2 | C16: =IF(Hypothèses!C16>0,Hypothèses!C14*Hypothèses!C15/Hypothèses!C16,0) -> 1.8666667 | D16: =IF(Hypothèses!D16>0,Hypothèses!D14*Hypothèses!D15/Hypothèses!D16,0) -> 1.5
A18: UNIT ECONOMICS
A19: CAC demandeur (€) | B19: =Hypothèses!B24 -> 80 | C19: =Hypothèses!C24 -> 60 | D19: =Hypothèses!D24 -> 45
A20: LTV demandeur (€) | B20: =Hypothèses!B7*Hypothèses!B8*Hypothèses!B18/(1-Hypothèses!B19) -> 1920 | C20: =Hypothèses!C7*Hypothèses!C8*Hypothèses!C18/(1-Hypothèses!C19) -> 3754.6667 | D20: =Hypothèses!D7*Hypothèses!D8*Hypothèses!D18/(1-Hypothèses!D19) -> 6428.5714
A21: Ratio LTV/CAC | B21: =B20/B19 -> 24 | C21: =C20/C19 -> 62.577778 | D21: =D20/D19 -> 142.85714
A23: RENTABILITÉ
A24: EBITDA (€) | B24: ='Coûts & P&L'!B25 -> -11303.333 | C24: ='Coûts & P&L'!C25 -> -80019.667 | D24: ='Coûts & P&L'!D25 -> 345850
A25: Marge EBITDA | B25: ='Coûts & P&L'!B26 -> -0.19623843 | C25: ='Coûts & P&L'!C26 -> -0.31573416 | D25: ='Coûts & P&L'!D26 -> 0.38427778
A26: Trésorerie (€) | B26: =Trésorerie!B10 -> 25696.667 | C26: =Trésorerie!C10 -> -62323 | D26: =Trésorerie!D10 -> 268527

Sheet Mode d'emploi
A1: MODE D'EMPLOI — BP MARKETPLACE
A4: Ce template est conçu pour les marketplaces et plateformes (biens, services, freelance, location...).
A6: ÉTAPE 1 : Onglet « Plan stratégique » — Décrivez votre projet, votre marché, vos milestones.
A7: ÉTAPE 2 : Onglet « Hypothèses » — Remplissez les cellules jaunes :
A8: • VOLUMÉTRIE : combien de transactions/mois, quel panier moyen, quelle commission
A9: • OFFRE/DEMANDE : combien d'offreurs/demandeurs, quel taux d'activité
A10: • ACQUISITION : coût pour recruter offreurs et demandeurs
A11: • COÛTS : frais de paiement, infrastructure, équipe
A12: • FINANCEMENT : apports, subventions, levée prévue
A13: ÉTAPE 3 : Les onglets Revenus, Coûts & P&L, Trésorerie et KPIs se calculent automatiquement.
A15: CONVENTIONS : Jaune = à remplir | Gris italique = exemple | Vert = résultat clé | Orange = à surveiller | Rouge = alerte
A17: Astuce : demandez à Sam (Agent Finance FounderAI) de calibrer vos hypothèses marketplace !
