Workbook

Sheet Plan stratégique
A1: BUSINESS PLAN SEED — MODÈLE SAAS
A2: Template FounderAI • Les cellules jaunes sont à remplir (exemples en gris à écraser)
A4: IDENTITÉ DU PROJET
A5: Nom de la startup | B5: ExempleSaaS | C5: Votre nom de startup
A6: Secteur d'activité | B6: SaaS B2B — RH Tech | C6: Ex: FinTech, EdTech, HealthTech...
A7: Date de création | B7: Janvier 2026
A8: Fondateur(s) | B8: Marie Dupont (CEO), Paul Martin (CTO) | C8: Noms et rôles
A9: Localisation | B9: Paris, France
A10: Stade actuel | B10: MVP lancé, 5 beta-testeurs | C10: Idéation / MVP / Beta / 1ers clients
A12: PROBLÈME & SOLUTION
A13: Problème résolu | B13: Les PME passent 15h/mois sur la gestion administrative RH sans outils adaptés
A14: Solution proposée | B14: Plateforme SaaS automatisant la paie, les congés et le suivi RH pour les PME de 5-50 salariés
A15: Proposition de valeur unique | B15: Mise en place en 24h, sans formation, 3x moins cher que les solutions existantes
A17: MARCHÉ
A18: TAM (marché total) | B18: 2,5 Mds€ — Marché européen des logiciels RH PME | C18: Taille totale du marché
A19: SAM (marché adressable) | B19: 400 M€ — PME françaises 5-50 salariés | C19: Part que vous pouvez atteindre
A20: SOM (objectif 3 ans) | B20: 2 M€ — 1 500 clients à 1 400€/an | C20: Objectif réaliste à 3 ans
A21: Client idéal (ICP) | B21: DRH ou dirigeant de PME, 10-30 salariés, France, pas d'outil RH | C21: Profil type de votre acheteur
A23: MILESTONES 18 MOIS
A24: M1-M3 | B24: MVP finalisé, 20 beta-testeurs, validation product-market fit
A25: M4-M6 | B25: Produit en production, 50 clients payants, 3K€ MRR
A26: M7-M12 | B26: 200 clients, 15K€ MRR, 1er commercial recruté
A27: M13-M18 | B27: 500 clients, 40K€ MRR, préparation Seed
A29: MODÈLE ÉCONOMIQUE
A30: Type de revenus | B30: Abonnement SaaS mensuel/annuel, 3 tiers de prix
A31: Avantage concurrentiel | B31: Simplicité d'usage + prix agressif + intégration paie native

Sheet Hypothèses
A1: HYPOTHÈSES — À REMPLIR EN PRIORITÉ
A2: Toutes les cellules jaunes alimentent automatiquement le reste du BP. Écrasez les exemples gris.
A4: PRICING
A5: Offre | B5: Prix/mois (€ HT) | C5: % du mix clients | D5: ARPU annuel (€) | E5: Notes
A6: Offre Starter | B6: 29 | C6: 0.5 | D6: =B6*12 -> 348 | E6: Fonctionnalités de base
A7: Offre Pro | B7: 79 | C7: 0.35 | D7: =B7*12 -> 948 | E7: Toutes les fonctionnalités
A8: Offre Premium | B8: 199 | C8: 0.15 | D8: =B8*12 -> 2388 | E8: Support prioritaire + API
A9: ARPU moyen pondéré (€/an) | D9: =SUMPRODUCT(C6:C8,D6:D8) -> 864 | E9: Calculé auto — ne pas modifier
A10: Engagement annuel (% clients) | B10: 0.3 | E10: % clients qui paient à l'année (remise ~15%)
A12: ACQUISITION CLIENTS
B13: Année 1 | C13: Année 2 | D13: Année 3 | E13: Notes
A14: Nouveaux clients / mois (moyenne) | B14: 10 | C14: 35 | D14: 75 | E14: Croissance progressive
A15: Taux de churn mensuel | B15: 0.06 | C15: 0.045 | D15: 0.03 | E15: Objectif < 5% dès Y2
A16: Taux conversion essai → payant | B16: 0.08 | C16: 0.12 | D16: 0.15 | E16: Essai gratuit 14 jours
A17: Coût d'acquisition client (CAC) € | B17: 50 | C17: 40 | D17: 30 | E17: Tout compris (ads + temps)
A18: Durée essai gratuit (jours) | B18: 14 | C18: 14 | D18: 14
A20: Clients payants fin d'année (calculé) | B20: =ROUND(B14*12*(1-B15)^6,0) -> 83 | C20: =ROUND(C14*12*(1-C15)^6,0) -> 319 | D20: =ROUND(D14*12*(1-D15)^6,0) -> 750 | E20: nouveaux x 12 x (1-churn)^6 approx.
A22: COÛTS VARIABLES UNITAIRES
A23: Poste de coût | B23: Coût/client/mois (€) | E23: Notes
A24: Hébergement / infra cloud | B24: 1.5 | E24: Serveurs, DB, CDN
A25: Coûts API / services tiers | B25: 0.5 | E25: APIs externes consommées
A26: Support client (coût unitaire) | B26: 2 | E26: Part du support par client
A27: Frais de paiement (% du CA) | B27: 0.029 | E27: Stripe, GoCardless...
A28: Total coût variable / client / mois | B28: =SUM(B24:B26) -> 4 | E28: Hors frais de paiement (% du CA)
A30: COÛTS FIXES MENSUELS (OPEX)
A31: Poste | B31: Année 1 /mois | C31: Année 2 /mois | D31: Année 3 /mois | E31: Notes
A32: Loyer / coworking | B32: 0 | C32: 300 | D32: 800 | E32: Télétravail Y1, coworking Y2
A33: Abonnements IT & outils | B33: 150 | C33: 300 | D33: 500 | E33: GitHub, Figma, CRM, analytics...
A34: Comptabilité / juridique | B34: 200 | C34: 400 | D34: 500 | E34: Expert-comptable
A35: Marketing & contenu | B35: 300 | C35: 1500 | D35: 3000 | E35: SEO, ads, events
A36: Assurances | B36: 50 | C36: 100 | D36: 150 | E36: RC Pro
A37: Divers / imprévus | B37: 100 | C37: 300 | D37: 500 | E37: Déplacements, repas, événements
A38: Total OPEX / mois | B38: =SUM(B32:B37) -> 800 | C38: =SUM(C32:C37) -> 2900 | D38: =SUM(D32:D37) -> 5450
A39: Total OPEX / an | B39: =B38*12 -> 9600 | C39: =C38*12 -> 34800 | D39: =D38*12 -> 65400
A41: ÉQUIPE & MASSE SALARIALE
A42: Poste | B42: Mois d'entrée | C42: Brut annuel (€) | E42: Notes
A43: Fondateur 1 | B43: 1 | C43: 0 | E43: Pas de salaire au début
A44: Fondateur 2 / Associé | B44: 1 | C44: 0 | E44: Optionnel
A45: 1er recrutement | B45: 10 | C45: 35000 | E45: Dev, commercial ou ops
A46: 2ème recrutement | B46: 18 | C46: 38000
...

Sheet Revenus
A1: PROJECTIONS DE REVENUS
A2: Calculé automatiquement à partir de l'onglet Hypothèses
B4: M1 | C4: M2 | D4: M3 | E4: M4 | F4: M5 | G4: M6 | H4: M7 | I4: M8 | J4: M9 | K4: M10 | L4: M11 | M4: M12 | N4: Q1 Y2 | O4: Q2 Y2 | P4: Q3 Y2 | Q4: Q4 Y2 | R4: Année 3 | S4: TOTAL
A5: Nouveaux clients (période) | B5: =Hypothèses!B14 -> 10 | C5: =Hypothèses!B14 -> 10 | D5: =Hypothèses!B14 -> 10 | E5: =Hypothèses!B14 -> 10 | F5: =Hypothèses!B14 -> 10 | G5: =Hypothèses!B14 -> 10 | H5: =Hypothèses!B14 -> 10 | I5: =Hypothèses!B14 -> 10 | J5: =Hypothèses!B14 -> 10 | K5: =Hypothèses!B14 -> 10 | L5: =Hypothèses!B14 -> 10 | M5: =Hypothèses!B14 -> 10 | N5: =Hypothèses!C14*3 -> 105 | O5: =Hypothèses!C14*3 -> 105 | P5: =Hypothèses!C14*3 -> 105 | Q5: =Hypothèses!C14*3 -> 105 | R5: =Hypothèses!D14*12 -> 900
A6: Clients perdus (churn) | B6: =0 -> 0 | C6: =-ROUND(B7*Hypothèses!$B$15,0) -> -1 | D6: =-ROUND(C7*Hypothèses!$B$15,0) -> -1 | E6: =-ROUND(D7*Hypothèses!$B$15,0) -> -2 | F6: =-ROUND(E7*Hypothèses!$B$15,0) -> -2 | G6: =-ROUND(F7*Hypothèses!$B$15,0) -> -3 | H6: =-ROUND(G7*Hypothèses!$B$15,0) -> -3 | I6: =-ROUND(H7*Hypothèses!$B$15,0) -> -3 | J6: =-ROUND(I7*Hypothèses!$B$15,0) -> -4 | ... M6: =-ROUND(L7*Hypothèses!$B$15,0) -> -5 | N6: =-ROUND(M7*Hypothèses!$C$15*3,0) -> -12 | O6: =-ROUND(N7*Hypothèses!$C$15*3,0) -> -24 | P6: =-ROUND(O7*Hypothèses!$C$15*3,0) -> -35 | Q6: =-ROUND(P7*Hypothèses!$C$15*3,0) -> -45 | R6: =-ROUND(Q7*Hypothèses!$D$15*12,0) -> -141
A7: Clients payants (fin de période) | B7: =B5+B6 -> 10 | C7: =B7+C5+C6 -> 19 | D7: =C7+D5+D6 -> 28 | E7: =D7+E5+E6 -> 36 | F7: =E7+F5+F6 -> 44 | G7: =F7+G5+G6 -> 51 | H7: =G7+H5+H6 -> 58 | I7: =H7+I5+I6 -> 65 | J7: =I7+J5+J6 -> 71 | ... R7: =Q7+R5+R6 -> 1150 | S7: =R7 -> 1150
A8: Clients moyens (période) | B8: =B7/2 -> 5 | C8: =(B7+C7)/2 -> 14.5 | D8: =(C7+D7)/2 -> 23.5 | E8: =(D7+E7)/2 -> 32 | F8: =(E7+F7)/2 -> 40 | G8: =(F7+G7)/2 -> 47.5 | H8: =(G7+H7)/2 -> 54.5 | I8: =(H7+I7)/2 -> 61.5 | J8: =(I7+J7)/2 -> 68 | ... R8: =(Q7+R7)/2 -> 770.5
A9: ARPU / période (€) | B9: =Hypothèses!$D$9/12 -> 72 | C9: =Hypothèses!$D$9/12 -> 72 | D9: =Hypothèses!$D$9/12 -> 72 | E9: =Hypothèses!$D$9/12 -> 72 | F9: =Hypothèses!$D$9/12 -> 72 | G9: =Hypothèses!$D$9/12 -> 72 | H9: =Hypothèses!$D$9/12 -> 72 | I9: =Hypothèses!$D$9/12 -> 72 | ... M9: =Hypothèses!$D$9/12 -> 72 | N9: =Hypothèses!$D$9/4 -> 216 | O9: =Hypothèses!$D$9/4 -> 216 | P9: =Hypothèses!$D$9/4 -> 216 | Q9: =Hypothèses!$D$9/4 -> 216 | R9: =Hypothèses!$D$9 -> 864
A10: CA Abonnements | B10: =B8*B9 -> 360 | C10: =C8*C9 -> 1044 | D10: =D8*D9 -> 1692 | E10: =E8*E9 -> 2304 | F10: =F8*F9 -> 2880 | G10: =G8*G9 -> 3420 | H10: =H8*H9 -> 3924 | I10: =I8*I9 -> 4428 | ... R10: =R8*R9 -> 665712 | S10: =SUM(B10:R10) -> 926172
A12: RÉCAPITULATIF ANNUEL
B13: Année 1 | C13: Année 2 | D13: Année 3
A14: CA Total (€) | B14: =SUM(B10:M10) -> 42084 | C14: =SUM(N10:Q10) -> 218376 | D14: =R10 -> 665712
A15: Clients fin d'année | B15: =M7 -> 87 | C15: =Q7 -> 391 | D15: =R7 -> 1150
A16: MRR fin d'année (€) | B16: =B15*Hypothèses!$D$9/12 -> 6264 | C16: =C15*Hypothèses!$D$9/12 -> 28152 | D16: =D15*Hypothèses!$D$9/12 -> 82800
A17: ARR fin d'année (€) | B17: =B16*12 -> 75168 | C17: =C16*12 -> 337824 | D17: =D16*12 -> 993600
A18: Croissance CA (%) | B18: ="-" -> - | C18: =IF(B14>0,(C14-B14)/B14,0) -> 4.1890505 | D18: =IF(C14>0,(D14-C14)/C14,0) -> 2.0484669

Sheet Coûts & P&L
A1: STRUCTURE DE COÛTS & COMPTE DE RÉSULTAT
A2: Calculé automatiquement — modifiez les hypothèses dans l'onglet Hypothèses
B4: Année 1 | C4: Année 2 | D4: Année 3 | E4: Formule / Notes
A5: COÛTS VARIABLES
A6: Coûts unitaires × clients | B6: =-Hypothèses!B28*Revenus!B15*12 -> -4176 | C6: =-Hypothèses!B28*Revenus!C15*12 -> -18768 | D6: =-Hypothèses!B28*Revenus!D15*12 -> -55200 | E6: Coût unit. × clients × 12 mois
A7: Frais de paiement (% CA) | B7: =-Revenus!B14*Hypothèses!B27 -> -1220.436 | C7: =-Revenus!C14*Hypothèses!B27 -> -6332.904 | D7: =-Revenus!D14*Hypothèses!B27 -> -19305.648 | E7: Stripe / paiement
A8: Total coûts variables | B8: =SUM(B6:B7) -> -5396.436 | C8: =SUM(C6:C7) -> -25100.904 | D8: =SUM(D6:D7) -> -74505.648
A10: COÛTS FIXES (OPEX)
A11: Total OPEX annuel | B11: =Hypothèses!B39 -> 9600 | C11: =Hypothèses!C39 -> 34800 | D11: =Hypothèses!D39 -> 65400 | E11: Depuis onglet Hypothèses
A12: Total coûts fixes | B12: =-ABS(B11) -> -9600 | C12: =-ABS(C11) -> -34800 | D12: =-ABS(D11) -> -65400
A14: MASSE SALARIALE
A15: Masse salariale chargée | B15: =Hypothèses!B53 -> 21145.833 | C15: =Hypothèses!C53 -> 145120.83 | D15: =Hypothèses!D53 -> 214600
A16: Total masse salariale | B16: =-ABS(B15) -> -21145.833 | C16: =-ABS(C15) -> -145120.83 | D16: =-ABS(D15) -> -214600
A18: COMPTE DE RÉSULTAT
B19: Année 1 | C19: Année 2 | D19: Année 3
A20: Chiffre d'affaires | B20: =Revenus!B14 -> 42084 | C20: =Revenus!C14 -> 218376 | D20: =Revenus!D14 -> 665712
A21: Coûts variables | B21: =B8 -> -5396.436 | C21: =C8 -> -25100.904 | D21: =D8 -> -74505.648
A22: Marge brute | B22: =B20+B21 -> 36687.564 | C22: =C20+C21 -> 193275.1 | D22: =D20+D21 -> 591206.35
A23: % Marge brute | B23: =IF(B20=0,0,B22/B20) -> 0.87176989 | C23: =IF(C20=0,0,C22/C20) -> 0.88505649 | D23: =IF(D20=0,0,D22/D20) -> 0.88808126
A24: Coûts fixes (OPEX) | B24: =B12 -> -9600 | C24: =C12 -> -34800 | D24: =D12 -> -65400
A25: Masse salariale | B25: =B16 -> -21145.833 | C25: =C16 -> -145120.83 | D25: =D16 -> -214600
A26: EBITDA | B26: =B22+B24+B25 -> 5941.7307 | C26: =C22+C24+C25 -> 13354.263 | D26: =D22+D24+D25 -> 311206.35
A27: % Marge EBITDA | B27: =IF(B20=0,0,B26/B20) -> 0.1411874 | C27: =IF(C20=0,0,C26/C20) -> 0.061152611 | D27: =IF(D20=0,0,D26/D20) -> 0.46747896

Sheet Trésorerie
A1: PLAN DE TRÉSORERIE
B3: Année 1 | C3: Année 2 | D3: Année 3 | E3: Notes
A4: Trésorerie début de période | B4: =Hypothèses!B62 -> 15000 | C4: =B12 -> 33941.731 | D4: =C12 -> 42295.993 | E4: total financement en Y1
A6: Encaissements clients | B6: =Revenus!B14 -> 42084 | C6: =Revenus!C14 -> 218376 | D6: =Revenus!D14 -> 665712
A7: Décaissements exploitation | B7: ='Coûts & P&L'!B26-'Coûts & P&L'!B20 -> -36142.269 | C7: ='Coûts & P&L'!C26-'Coûts & P&L'!C20 -> -205021.74 | D7: ='Coûts & P&L'!D26-'Coûts & P&L'!D20 -> -354505.65
A8: Flux opérationnel | B8: =B6+B7 -> 5941.7307 | C8: =C6+C7 -> 13354.263 | D8: =D6+D7 -> 311206.35
A9: Investissements (CAPEX) | B9: -2000 | C9: -5000 | D9: -10000 | E9: Matériel, licences, brevets...
A10: Apports de financement | B10: =Hypothèses!B62 -> 15000 | C10: 0 | D10: 0 | E10: Levée, subventions entrées en année
A11: Flux net total | B11: =B8+B9+B10 -> 18941.731 | C11: =C8+C9+C10 -> 8354.2627 | D11: =D8+D9+D10 -> 301206.35
A12: Trésorerie fin de période | B12: =B4+B11 -> 33941.731 | C12: =C4+C11 -> 42295.993 | D12: =D4+D11 -> 343502.35
A14: MÉTRIQUES DE TRÉSORERIE
A15: Burn rate mensuel | B15: =IF(B11<0,-B11/12,0) -> 0 | C15: =IF(C11<0,-C11/12,0) -> 0 | D15: =IF(D11<0,-D11/12,0) -> 0
A16: Runway (mois) | B16: =IF(B15>0,B4/B15,99) -> 99 | C16: =IF(C15>0,C4/C15,99) -> 99 | D16: =IF(D15>0,D4/D15,99) -> 99 | E16: Nombre de mois de survie au burn actuel
A17: Besoin de financement | B17: =IF(B12<0,-B12,0) -> 0 | C17: =IF(C12<0,-C12,0) -> 0 | D17: =IF(D12<0,-D12,0) -> 0 | E17: Montant nécessaire si tréso négative

Sheet KPIs
A1: TABLEAU DE BORD — KPIs SEED
A2: Tous les indicateurs sont calculés automatiquement
A4: INDICATEUR | B4: Année 1 | C4: Année 2 | D4: Année 3
A5: CROISSANCE
A6: Clients payants (fin) | B6: =Revenus!B15 -> 87 | C6: =Revenus!C15 -> 391 | D6: =Revenus!D15 -> 1150
A7: ARR (€) | B7: =Revenus!B17 -> 75168 | C7: =Revenus!C17 -> 337824 | D7: =Revenus!D17 -> 993600
A8: MRR (€) | B8: =Revenus!B16 -> 6264 | C8: =Revenus!C16 -> 28152 | D8: =Revenus!D16 -> 82800
A9: CA total (€) | B9: =Revenus!B14 -> 42084 | C9: =Revenus!C14 -> 218376 | D9: =Revenus!D14 -> 665712
A11: UNIT ECONOMICS
A12: ARPU annuel (€) | B12: =Hypothèses!$D$9 -> 864 | C12: =Hypothèses!$D$9 -> 864 | D12: =Hypothèses!$D$9 -> 864
A13: CAC (€) | B13: =Hypothèses!B17 -> 50 | C13: =Hypothèses!C17 -> 40 | D13: =Hypothèses!D17 -> 30
A14: LTV estimée (€) | B14: =Hypothèses!$D$9/(Hypothèses!B15*12) -> 1200 | C14: =Hypothèses!$D$9/(Hypothèses!C15*12) -> 1600 | D14: =Hypothèses!$D$9/(Hypothèses!D15*12) -> 2400
A15: Ratio LTV / CAC | B15: =B14/B13 -> 24 | C15: =C14/C13 -> 40 | D15: =D14/D13 -> 80
A16: Churn mensuel | B16: =Hypothèses!B15 -> 0.06 | C16: =Hypothèses!C15 -> 0.045 | D16: =Hypothèses!D15 -> 0.03
A17: Payback (mois) | B17: =Hypothèses!B17/(Hypothèses!$D$9/12) -> 0.69444444 | C17: =Hypothèses!C17/(Hypothèses!$D$9/12) -> 0.55555556 | D17: =Hypothèses!D17/(Hypothèses!$D$9/12) -> 0.41666667
A19: RENTABILITÉ
A20: EBITDA (€) | B20: ='Coûts & P&L'!B26 -> 5941.7307 | C20: ='Coûts & P&L'!C26 -> 13354.263 | D20: ='Coûts & P&L'!D26 -> 311206.35
A21: Marge EBITDA | B21: ='Coûts & P&L'!B27 -> 0.1411874 | C21: ='Coûts & P&L'!C27 -> 0.061152611 | D21: ='Coûts & P&L'!D27 -> 0.46747896
A22: Trésorerie (€) | B22: =Trésorerie!B12 -> 33941.731 | C22: =Trésorerie!C12 -> 42295.993 | D22: =Trésorerie!D12 -> 343502.35
A23: Runway (mois) | B23: =Trésorerie!B16 -> 99 | C23: =Trésorerie!C16 -> 99 | D23: =Trésorerie!D16 -> 99
A24: Besoin financement (€) | B24: =Trésorerie!B17 -> 0 | C24: =Trésorerie!C17 -> 0 | D24: =Trésorerie!D17 -> 0

Sheet Mode d'emploi
A1: MODE D'EMPLOI — COMMENT REMPLIR CE BP
A4: ÉTAPE 1 : Remplir l'onglet « Plan stratégique »
A5: Écrasez les exemples en gris avec vos propres informations. Cet onglet est qualitatif — il raconte votre histoire.
A7: ÉTAPE 2 : Remplir l'onglet « Hypothèses »
A8: C'est le cœur du modèle. Toutes les cellules jaunes alimentent le reste du BP :
A9: • PRICING : Définissez vos 3 offres, leur prix et la répartition client estimée
A10: • ACQUISITION : Combien de clients/mois, quel churn, quel CAC ?
A11: • COÛTS VARIABLES : Combien coûte chaque client en infrastructure ?
A12: • COÛTS FIXES : Vos dépenses mensuelles hors salaires
A13: • ÉQUIPE : Quels recrutements, quand, à quel salaire ?
A14: • FINANCEMENT : Apports fondateurs, subventions, levée prévue
A16: ÉTAPE 3 : Vérifier les résultats
... A32: Exemple : « Sam, aide-moi à estimer mon CAC pour un SaaS B2B vendu 79€/mois aux PME en France »
